Workbook
Name 部件与系统: #REF!
Name 部件与系统: #REF!
Name 原材料: #REF!

Sheet 全球新能源汽车销量
G1: 全球新能源乘用车销量(万辆) | Q1: 全球不同动力类型的新能源乘用车销量(万辆)
F14: 万辆 | G14: 月份 | H14: 2024 | I14: 2023 | J14: 2022 | K14: 2021 | L14: 2020 | M14: YOY | N14: 环比 | P14: 万辆 | Q14: 月份 | R14: EV | S14: YOY(EV) | T14: PHEV | U14: YOY(PHEV) | V14: 合计
G15: 1 | H15: 103.6146 | I15: 62.8839 | J15: 63.4186 | K15: 31.4715 | L15: 15.769 | M15: =I15/J15-1 -> -0.0084312804 | N15: =I15/J26-1 -> -0.50961563 | Q15: 42736 | R15: 3.0149 | S15: - | T15: 1.6542 | U15: - | V15: 4.6957
G16: 2 | H16: 81.7713 | I16: 79.7232 | J16: 56.7087 | K16: 26.2383 | L16: 12.9804 | M16: =I16/J16-1 -> 0.4058372 | N16: =I16/I15-1 -> 0.26778396 | O16: =H16/I16-1 -> 0.025690138 | Q16: 42767 | R16: 4.1 | S16: - | T16: 2.0113 | U16: - | V16: 6.1395
G17: 3 | I17: 107.3622 | J17: 81.6744 | K17: 48.7645 | L17: 16.6189 | M17: =I17/J17-1 -> 0.31451471 | N17: =I17/I16-1 -> 0.34668704 | O17: =H16/H15-1 -> -0.21081295 | Q17: 42795 | R17: 7.1043 | S17: - | T17: 2.7541 | U17: - | V17: 9.8823
G18: 4 | I18: 89.5868 | J18: 54.2854 | K18: 38.7398 | L18: 10.5022 | M18: =I18/J18-1 -> 0.65029271 | N18: =I18/I17-1 -> -0.16556479 | Q18: 42826 | R18: 4.6145 | S18: - | T18: 2.2672 | U18: - | V18: 6.8999
G19: 5 | I19: 101.1595 | J19: 70.6442 | K19: 44.2849 | L19: 13.8239 | M19: =I19/J19-1 -> 0.43195761 | N19: =I19/I18-1 -> 0.12917863 | Q19: 42856 | R19: 5.9558 | S19: - | T19: 3.1215 | U19: - | V19: 9.1116 | MA19: =I15/J15-1 -> -0.0084312804
G20: 6 | I20: 116.2203 | J20: 89.132 | K20: 53.8183 | L20: 20.1423 | M20: =I20/J20-1 -> 0.30391218 | N20: =I20/I19-1 -> 0.14888172 | Q20: 42887 | R20: 6.8753 | S20: - | T20: 3.3922 | U20: - | V20: 10.2937
G21: 7 | I21: 104.5893 | J21: 83.0791 | K21: 47.6172 | L21: 22.7704 | M21: =I21/J21-1 -> 0.25891229 | N21: =I21/I20-1 -> -0.10007718 | Q21: 42917 | R21: 6.0346 | S21: - | T21: 3.0892 | U21: - | V21: 9.1471
G22: 8 | I22: 124.2135 | J22: 90.1628 | K22: 51.713 | L22: 22.314 | M22: =I22/J22-1 -> 0.37765797 | N22: =I22/I21-1 -> 0.18763105 | Q22: 42948 | R22: 7.0687 | S22: - | T22: 3.0423 | U22: - | V22: 10.1235
G23: 9 | I23: 130.5057 | J23: 103 | K23: 64.056 | L23: 31.9715 | M23: =I23/J23-1 -> 0.26704563 | N23: =I23/I22-1 -> 0.05065633 | Q23: 42979 | R23: 9.1085 | S23: - | T23: 3.746 | U23: - | V23: 12.8835
G24: 10 | I24: 129.9028 | J24: 98.3218 | K24: 63.0817 | L24: 32.8704 | M24: =I24/J24-1 -> 0.32120038 | N24: =I24/I23-1 -> -0.0046197216 | Q24: 43009 | R24: 7.8972 | S24: - | T24: 3.3527 | U24: - | V24: 11.2809
G25: 11 | I25: 141.1452 | J25: 110.9834 | K25: 73.4662 | L25: 37.1021 | M25: =I25/J25-1 -> 0.27176857 | N25: =I25/I24-1 -> 0.086544709 | Q25: 43040 | R25: 9.7077 | S25: - | T25: 3.9982 | U25: - | V25: 13.7405
G26: 12 | I26: 161.495 | J26: 128.2339 | K26: 86.386 | L26: 50.2485 | M26: =I26/J26-1 -> 0.25937837 | N26: =I26/I25-1 -> 0.14417635 | Q26: 43070 | R26: 12.2162 | S26: - | T26: 4.222 | U26: - | V26: 16.4765
G27: 合计 | H27: =SUM(H15:H26) -> 185.3859 | I27: =SUM(I15:I26) -> 1348.7874 | J27: =SUM(J15:J26) -> 1029.6443 | K27: =SUM(K15:K26) -> 629.6374 | L27: 287.1136 | Q27: 43101 | R27: 4.1916 | S27: =R27/R15-1 -> 0.39029487 | T27: 3.2173 | U27: 0.94492806 | V27: 7.4529
Q28: 43132 | R28: 4.3375 | S28: =R28/R16-1 -> 0.057926829 | T28: 3.0812 | U28: 0.53194451 | V28: 7.4738
G29: 世界汽车组织(OICA)、乘联会 | Q29: 43160 | R29: 8.5142 | S29: =R29/R17-1 -> 0.19845727 | T29: 4.4799 | U29: 0.62662939 | V29: 13.0325
Q30: 43191 | R30: 8.1372 | S30: =R30/R18-1 -> 0.76339798 | T30: 4.2408 | U30: 0.87050106 | V30: 12.4221
Q31: 43221 | R31: 10.568 | S31: =R31/R19-1 -> 0.77440478 | T31: 4.5904 | U31: 0.47057504 | V31: 15.1882
Q32: 43252 | R32: 8.6441 | S32: =R32/R20-1 -> 0.25726877 | T32: 5.1982 | U32: 0.53239785 | V32: 13.884
Q33: 43282 | R33: 8.7699 | S33: =R33/R21-1 -> 0.45326948 | T33: 4.6558 | U33: 0.50712158 | V33: 13.488
Q34: 43313 | R34: 10.3241 | S34: =R34/R22-1 -> 0.4605373 | T34: 5.1179 | U34: 0.68224698 | V34: 15.4748
Q35: 43344 | R35: 13.4085 | S35: =R35/R23-1 -> 0.47208651 | T35: 5.107 | U35: 0.36332088 | V35: 18.5507
Q36: 43374 | R36: 14.4942 | S36: =R36/R24-1 -> 0.83535937 | T36: 4.9603 | U36: 0.47949414 | V36: 19.4863
Q37: 43405 | R37: 16.3894 | S37: =R37/R25-1 -> 0.68828868 | T37: 5.3938 | U37: 0.34905708 | V37: 21.8301
Q38: 43435 | R38: 20.3258 | S38: =R38/R26-1 -> 0.66383982 | T38: 5.4016 | U38: 0.27939365 | V38: 25.771
Q39: 43466 | R39: 11.8236 | S39: =R39/R27-1 -> 1.8207844 | T39: 3.6759 | U39: 0.14254188 | V39: 15.5192
Q40: 43497 | R40: 8.1097 | S40: =R40/R28-1 -> 0.86967147 | T40: 3.0103 | U40: -0.023010515 | V40: 11.1678
Q41: 43525 | R41: 15.6303 | S41: =R41/R29-1 -> 0.83579197 | T41: 4.814 | U41: 0.074577558 | V41: 20.4943
... Q62: 44166 | R62: 36.9355 | S62: =R62/R50-1 -> 0.80539534 | T62: 13.2172 | U62: 1.6870203 | V62: 50.2485
Q63: 44197 | R63: 21.4716 | S63: =R63/R51-1 -> 1.1087181 | T63: 9.9339 | U63: =T63/T51-1 -> 0.78728342 | V63: 31.4715
Q64: 44228 | R64: 17.0094 | S64: =R64/R52-1 -> 1.0157855 | T64: 9.1133 | U64: =T64/T52-1 -> 1.0469206 | V64: 26.2383
Q65: 44256 | R65: 31.8389 | S65: =R65/R53-1 -> 1.6757627 | T65: 16.7148 | U65: =T65/T53-1 -> 2.608004 | V65: 48.7645
Q66: 44287 | R66: 25.5787 | S66: =R66/R54-1 -> 2.6366441 | T66: 12.9614 | U66: =T66/T54-1 -> 2.8337129 | V66: 38.7398
Q67: 44317 | R67: 30.1601 | S67: =R67/R55-1 -> 2.2471765 | T67: 13.9768 | U67: =T67/T55-1 -> 2.1128037 | V67: 44.2849
Q68: 44348 | R68: 37.2538 | S68: =R68/R56-1 -> 1.7726647 | T68: 16.4336 | U68: =T68/T56-1 -> 1.4698067 | V68: 53.8183
Q69: 44378 | R69: 32.4004 | S69: =R69/R57-1 -> 1.2109674 | T69: 15.1172 | U69: =T69/T57-1 -> 0.88251996 | V69: 47.6172
Q70: 44409 | R70: 37.9016 | S70: =R70/R58-1 -> 1.4137303 | T70: 13.7173 | U70: =T70/T58-1 -> 1.103203 | V70: 51.713
Q71: 44440 | R71: 47.3795 | S71: =R71/R59-1 -> 1.075754 | T71: 16.5113 | U71: =T71/T59-1 -> 0.821193 | V71: 64.056
Q72: 44470 | R72: 47.036 | S72: =R72/R60-1 -> 1.0821602 | T72: 15.8877 | U72: =T72/T60-1 -> 0.55911562 | V72: 63.0817
...

Sheet 全球新能源车分地区销量
A15: 地区划分全球新能源乘用车销量(万辆)
A16: 当月 | B16: 中国 | C16: 美国 | D16: 欧洲 | E16: 其他 | F16: 德国 | G16: 法国 | H16: 英国 | I16: 挪威 | J16: 意大利 | K16: 葡萄牙 | L16: 荷兰 | M16: 西班牙 | N16: 芬兰 | O16: 欧洲其他 | P16: 日本 | Q16: 韩国 | R16: 其他 | S16: 总计 | T16: 累计销量
A17: 43101 | B17: 3.2029 | C17: 1.2155 | D17: =SUM(F17:O17) -> 2.2358 | E17: =S17-B17-C17-D17 -> 0.7987 | F17: 0.5303 | G17: 0.2675 | H17: 0.308 | I17: 0.3693 | J17: 0.056 | K17: 0.0479 | L17: 0.1294 | M17: 0.0638 | N17: 0.037 | O17: 0.4266 | P17: 0.5825 | Q17: 0.1263 | R17: 0.0899 | S17: 7.4529 | T17: =S17 -> 7.4529
A18: 43132 | B18: 2.8496 | C18: 1.6912 | D18: =SUM(F18:O18) -> 2.1224 | E18: =S18-B18-C18-D18 -> 0.8106 | F18: 0.4719 | G18: 0.3591 | H18: 0.1511 | I18: 0.445 | J18: 0.0483 | K18: 0.0444 | L18: 0.1003 | M18: 0.0618 | N18: 0.0274 | O18: 0.4131 | P18: 0.5561 | Q18: 0.1234 | R18: 0.1311 | S18: 7.4738 | T18: =T17+S18 -> 14.9267
A19: 43160 | B19: 5.5719 | C19: 2.5566 | D19: =SUM(F19:O19) -> 3.9814 | E19: =S19-B19-C19-D19 -> 0.9226 | F19: 0.6878 | G19: 0.6331 | H19: 0.8385 | I19: 0.8041 | J19: 0.0859 | K19: 0.0592 | L19: 0.174 | M19: 0.0677 | N19: 0.0341 | O19: 0.597 | P19: 0.5198 | Q19: 0.1842 | R19: 0.2186 | S19: 13.0325 | T19: =T18+S19 -> 27.9592
A20: 43191 | B20: 7.3371 | C20: 1.9048 | D20: =SUM(F20:O20) -> 2.6515 | E20: =S20-B20-C20-D20 -> 0.5287 | F20: 0.556 | G20: 0.3412 | H20: 0.3323 | I20: 0.6118 | J20: 0.072 | K20: 0.0741 | L20: 0.0913 | M20: 0.0705 | N20: 0.0414 | O20: 0.4609 | P20: 0.217 | Q20: 0.1729 | R20: 0.1388 | S20: 12.4221 | T20: =T19+S20 -> 40.3813
A21: 43221 | B21: 9.2299 | C21: 2.4162 | D21: =SUM(F21:O21) -> 2.7107 | E21: =S21-B21-C21-D21 -> 0.8314 | F21: 0.4946 | G21: 0.3842 | H21: 0.4109 | I21: 0.5518 | J21: 0.1025 | K21: 0.0712 | L21: 0.1201 | M21: 0.0615 | N21: 0.0846 | O21: 0.4293 | P21: 0.3139 | Q21: 0.2598 | R21: 0.2577 | S21: 15.1882 | T21: =T20+S21 -> 55.5695
A22: 43252 | B22: 7.1741 | C22: 2.226 | D22: =SUM(F22:O22) -> 3.5834 | E22: =S22-B22-C22-D22 -> 0.9005 | F22: 0.5783 | G22: 0.5671 | H22: 0.5844 | I22: 0.7977 | J22: 0.0786 | K22: 0.0662 | L22: 0.2168 | M22: 0.0717 | N22: 0.0315 | O22: 0.5911 | P22: 0.3075 | Q22: 0.4104 | R22: 0.1826 | S22: 13.884 | T22: =T21+S22 -> 69.4535
A23: 43282 | B23: 7.1105 | C23: 2.8865 | D23: =SUM(F23:O23) -> 2.5333 | E23: =S23-B23-C23-D23 -> 0.9577 | F23: 0.6252 | G23: 0.3092 | H23: 0.3858 | I23: 0.3745 | J23: 0.1283 | K23: 0.0614 | L23: 0.1139 | M23: 0.0665 | N23: 0.0345 | O23: 0.434 | P23: 0.3667 | Q23: 0.3119 | R23: 0.2791 | S23: 13.488 | T23: =T22+S23 -> 82.9415
A24: 43313 | B24: 8.4259 | C24: 3.3218 | D24: =SUM(F24:O24) -> 2.7255 | E24: =S24-B24-C24-D24 -> 1.0016 | F24: 0.6023 | G24: 0.3091 | H24: 0.3482 | I24: 0.6109 | J24: 0.0447 | K24: 0.0592 | L24: 0.1627 | M24: 0.0602 | N24: 0.0393 | O24: 0.4889 | P24: 0.3512 | Q24: 0.2958 | R24: 0.3546 | S24: 15.4748 | T24: =T23+S24 -> 98.4163
A25: 43344 | B25: 9.8915 | C25: 4.4399 | D25: =SUM(F25:O25) -> 3.1535 | E25: =S25-B25-C25-D25 -> 1.0658 | F25: 0.4169 | G25: 0.4358 | H25: 0.6587 | I25: 0.6396 | J25: 0.0919 | K25: 0.071 | L25: 0.2885 | M25: 0.0767 | N25: 0.0258 | O25: 0.4486 | P25: 0.5054 | Q25: 0.3118 | R25: 0.2486 | S25: 18.5507 | T25: =T24+S25 -> 116.967
A26: 43374 | B26: 11.9792 | C26: 3.4616 | D26: =SUM(F26:O26) -> 3.0769 | E26: =S26-B26-C26-D26 -> 0.9686 | F26: 0.4788 | G26: 0.4739 | H26: 0.434 | I26: 0.6471 | J26: 0.1375 | K26: 0.0774 | L26: 0.1775 | M26: 0.0809 | N26: 0.0495 | O26: 0.5203 | P26: 0.3119 | Q26: 0.4439 | R26: 0.2128 | S26: 19.4863 | T26: =T25+S26 -> 136.4533
A27: 43405 | B27: 13.1263 | C27: 4.0785 | D27: =SUM(F27:O27) -> 3.4795 | E27: =S27-B27-C27-D27 -> 1.1458 | F27: 0.5766 | G27: 0.5725 | H27: 0.4237 | I27: 0.7004 | J27: 0.0344 | K27: 0.0919 | L27: 0.3339 | M27: 0.0949 | N27: 0.0358 | O27: 0.6154 | P27: 0.4172 | Q27: 0.5314 | R27: 0.1972 | S27: 21.8301 | T27: =T26+S27 -> 158.2834
A28: 43435 | B28: 16.0231 | C28: 5.0939 | D28: =SUM(F28:O28) -> 3.9511 | E28: =S28-B28-C28-D28 -> 0.7029 | F28: 0.6079 | G28: 0.643 | H28: 0.515 | I28: 0.7178 | J28: 0.0293 | K28: 0.0661 | L28: 0.6275 | M28: 0.2144 | N28: 0.0231 | O28: 0.507 | P28: 0.1971 | Q28: 0.2706 | R28: 0.2352 | S28: 25.771 | T28: =T27+S28 -> 184.0544
A29: 43466 | B29: 9.1137 | C29: 2.6445 | D29: =SUM(F29:O29) -> 3.117 | E29: =S29-B29-C29-D29 -> 0.644 | F29: 0.6655 | G29: 0.4616 | H29: 0.3222 | I29: 0.4705 | J29: 0.0556 | K29: 0.0989 | L29: 0.3277 | M29: 0.1031 | N29: 0.0089 | O29: 0.603 | P29: 0.3769 | Q29: 0.1009 | R29: 0.1662 | S29: 15.5192 | T29: =S29 -> 15.5192
A30: 43497 | B30: 5.0154 | C30: 2.443 | D30: =SUM(F30:O30) -> 3.095 | E30: =S30-B30-C30-D30 -> 0.6144 | F30: 0.6504 | G30: 0.4652 | H30: 0.1961 | I30: 0.5932 | J30: 0.0655 | K30: 0.086 | L30: 0.2458 | M30: 0.1225 | N30: 0.0099 | O30: 0.6604 | P30: 0.3454 | Q30: 0.1022 | R30: 0.1668 | S30: 11.1678 | T30: =T29+S30 -> 26.687
A31: 43525 | B31: 10.9789 | C31: 2.649 | D31: =SUM(F31:O31) -> 5.8069 | E31: =S31-B31-C31-D31 -> 1.0595 | F31: 0.997 | G31: 0.6764 | H31: 0.7955 | I31: 1.2767 | J31: 0.1112 | K31: 0.1292 | L31: 0.4823 | M31: 0.1963 | N31: 0.0197 | O31: 1.1226 | P31: 0.3967 | Q31: 0.4806 | R31: 0.1822 | S31: 20.4943 | T31: =S31 -> 20.4943
A32: 43556 | B32: 9.1045 | C32: 2.0594 | D32: =SUM(F32:O32) -> 3.6216 | E32: =S32-B32-C32-D32 -> 0.7 | F32: 0.8047 | G32: 0.5006 | H32: 0.3234 | I32: 0.5603 | J32: 0.1684 | K32: 0.0836 | L32: 0.2684 | M32: 0.1116 | N32: 0.018 | O32: 0.7826 | P32: 0.162 | Q32: 0.4133 | R32: 0.1247 | S32: 15.4855 | T32: =T31+S32 -> 35.9798
A33: 43586 | B33: 9.6993 | C33: 2.4793 | D33: =SUM(F33:O33) -> 3.5717 | E33: =S33-B33-C33-D33 -> 1.0319 | F33: 0.7548 | G33: 0.4539 | H33: 0.4069 | I33: 0.6102 | J33: 0.1616 | K33: 0.0907 | L33: 0.2644 | M33: 0.137 | N33: 0.0085 | O33: 0.6837 | P33: 0.2178 | Q33: 0.4702 | R33: 0.3439 | S33: 16.7822 | T33: =S33 -> 16.7822
A34: 43617 | B34: 13.4472 | C34: 2.7464 | D34: =SUM(F34:O34) -> 4.5798 | E34: =S34-B34-C34-D34 -> 1.0722 | F34: 0.7948 | G34: 0.6413 | H34: 0.443 | I34: 0.8868 | J34: 0.1992 | K34: 0.126 | L34: 0.46 | M34: 0.1459 | N34: 0.0222 | O34: 0.8606 | P34: 0.297 | Q34: 0.3936 | R34: 0.3816 | S34: 21.8456 | T34: =T33+S34 -> 38.6278
A35: 43647 | B35: 6.7283 | C35: 2.4838 | D35: =SUM(F35:O35) -> 3.4067 | E35: =S35-B35-C35-D35 -> 1.018 | F35: 0.9198 | G35: 0.4766 | H35: 0.381 | I35: 0.4428 | J35: 0.122 | K35: 0.083 | L35: 0.2288 | M35: 0.1087 | N35: 0.0143 | O35: 0.6297 | P35: 0.3559 | Q35: 0.3837 | R35: 0.2784 | S35: 13.6368 | T35: =S35 -> 13.6368
A36: 43678 | B36: 7.134 | C36: 2.708 | D36: =SUM(F36:O36) -> 3.455 | E36: =S36-B36-C36-D36 -> 0.8628 | F36: 0.8923 | G36: 0.3783 | H36: 0.4109 | I36: 0.5898 | J36: 0.0841 | K36: 0.0769 | L36: 0.3145 | M36: 0.0819 | N36: 0.013 | O36: 0.6133 | P36: 0.2975 | Q36: 0.2706 | R36: 0.2947 | S36: 14.1598 | T36: =T35+S36 -> 27.7966
A37: 43709 | B37: 6.5514 | C37: 2.7874 | D37: =SUM(F37:O37) -> 5.6972 | E37: =S37-B37-C37-D37 -> 1.054 | F37: 0.9363 | G37: 0.6192 | H37: 1.2184 | I37: 0.721 | J37: 0.1831 | K37: 0.1161 | L37: 0.8018 | M37: 0.1315 | N37: 0.0199 | O37: 0.9499 | P37: 0.5001 | Q37: 0.2373 | R37: 0.3166 | S37: 16.09 | T37: =S37 -> 16.09
A38: 43739 | B38: 6.6039 | C38: 2.5927 | D38: =SUM(F38:O38) -> 4.8908 | E38: =S38-B38-C38-D38 -> 0.687 | F38: 1.2288 | G38: 0.7016 | H38: 0.6306 | I38: 0.6096 | J38: 0.1212 | K38: 0.1413 | L38: 0.2969 | M38: 0.1918 | N38: 0.004 | O38: 0.965 | P38: 0.1672 | Q38: 0.2911 | R38: 0.2287 | S38: 14.7744 | T38: =T37+S38 -> 30.8644
A39: 43770 | B39: 7.9168 | C39: 2.9741 | D39: =SUM(F39:O39) -> 5.3253 | E39: =S39-B39-C39-D39 -> 0.7337 | F39: 1.1192 | G39: 0.6185 | H39: 0.8863 | I39: 0.595 | J39: 0.131 | K39: 0.1325 | L39: 0.7563 | M39: 0.1914 | N39: 0.0052 | O39: 0.8899 | P39: 0.2579 | Q39: 0.2844 | R39: 0.1914 | S39: 16.9499 | T39: =S39 -> 16.9499
A40: 43800 | B40: 13.9211 | C40: 3.5925 | D40: =SUM(F40:O40) -> 7.2998 | E40: =S40-B40-C40-D40 -> 0.6488 | F40: 0.9187 | G40: 0.8451 | H40: 0.9121 | I40: 0.5962 | J40: 0.1304 | K40: 0.1309 | L40: 2.1976 | M40: 0.1701 | N40: 0.0134 | O40: 1.3853 | P40: 0.2289 | Q40: 0.1852 | R40: 0.2347 | S40: 25.4622 | T40: =T39+S40 -> 42.4121
A41: 43831 | B41: 4.2945 | C41: 3.3544 | D41: =SUM(F41:O41) -> 7.4958 | E41: =S41-B41-C41-D41 -> 0.6243 | F41: 1.9533 | G41: 1.4955 | H41: 0.8653 | I41: 0.612 | J41: 0.4051 | K41: 0.1686 | L41: 0.3626 | M41: 0.3429 | N41: 0.0152 | O41: 1.2753 | P41: 0.1789 | Q41: 0.0783 | R41: 0.3671 | S41: 15.769 | T41: =S41 -> 15.769
A42: 43862 | B42: 1.5372 | C42: 3.1601 | D42: =SUM(F42:O42) -> 7.34 | E42: =S42-B42-C42-D42 -> 0.9431 | F42: 2.141 | G42: 1.3932 | H42: 0.461 | I42: 0.7044 | J42: 0.4554 | K42: 0.1643 | L42: 0.4235 | M42: 0.3353 | N42: 0.0108 | O42: 1.2511 | P42: 0.4294 | Q42: 0.2871 | R42: 0.2266 | S42: 12.9804 | T42: =T41+S42 -> 28.7494
A43: 43891 | B43: 5.6661 | C43: 1.9171 | D43: =SUM(F43:O43) -> 7.9754 | E43: =S43-B43-C43-D43 -> 1.0603 | F43: 2.0504 | G43: 0.7573 | H43: 1.7718 | I43: 0.9315 | J43: 0.1529 | K43: 0.1505 | L43: 0.433 | M43: 0.146 | N43: 0.0425 | O43: 1.5395 | P43: 0.2761 | Q43: 0.5448 | R43: 0.2394 | S43: 16.6189 | T43: =S43 -> 16.6189
A44: 43922 | B44: 5.8622 | C44: 0.9862 | D44: =SUM(F44:O44) -> 2.988 | E44: =S44-B44-C44-D44 -> 0.6658 | F44: 1.1312 | G44: 0.1635 | H44: 0.1377 | I44: 0.5089 | J44: 0.0568 | K44: 0.0525 | L44: 0.1727 | M44: 0.0212 | N44: 0.0146 | O44: 0.7289 | P44: 0.0807 | Q44: 0.4605 | R44: 0.1246 | S44: 10.5022 | T44: =T43+S44 -> 27.1211
A45: 43952 | B45: 6.9861 | C45: 1.4329 | D45: =SUM(F45:O45) -> 4.8478 | E45: =S45-B45-C45-D45 -> 0.5571 | F45: 1.4777 | G45: 0.7636 | H45: 0.3183 | I45: 0.5216 | J45: 0.3209 | K45: 0.0837 | L45: 0.2188 | M45: 0.1413 | N45: 0.0127 | O45: 0.9892 | P45: 0.0839 | Q45: 0.2895 | R45: 0.1837 | S45: 13.8239 | T45: =S45 -> 13.8239
A46: 43983 | B46: 8.3799 | C46: 1.8709 | D46: =SUM(F46:O46) -> 9.1698 | E46: =S46-B46-C46-D46 -> 0.7217 | F46: 2.1542 | G46: 2.1003 | H46: 1.3364 | I46: 0.7552 | J46: 0.4211 | K46: 0.1133 | L46: 0.4059 | M46: 0.2867 | N46: 0.0166 | O46: 1.5801 | P46: 0.1467 | Q46: 0.3142 | R46: 0.2608 | S46: 20.1423 | T46: =T45+S46 -> 33.9662
A47: 44013 | B47: 8.6575 | C47: 2.436 | D47: =SUM(F47:O47) -> 10.8609 | E47: =S47-B47-C47-D47 -> 0.816 | F47: 4.0223 | G47: 1.6417 | H47: 1.4762 | I47: 0.6663 | J47: 0.4164 | K47: 0.1833 | L47: 0.5142 | M47: 0.4368 | N47: 0.0116 | O47: 1.4921 | P47: 0.1598 | Q47: 0.416 | R47: 0.2402 | S47: 22.7704 | T47: =S47 -> 22.7704
A48: 44044 | B48: 9.8836 | C48: 2.8403 | D48: =SUM(F48:O48) -> 8.8128 | E48: =S48-B48-C48-D48 -> 0.7773 | F48: 3.1225 | G48: 1.0884 | H48: 0.8949 | I48: 0.752 | J48: 0.3935 | K48: 0.1621 | L48: 0.5635 | M48: 0.2975 | N48: 0.0193 | O48: 1.5191 | P48: 0.1197 | Q48: 0.373 | R48: 0.2846 | S48: 22.314 | T48: =T47+S48 -> 45.0844
A49: 44075 | B49: 12.6154 | C49: 3.4299 | D49: =SUM(F49:O49) -> 14.8081 | E49: =S49-B49-C49-D49 -> 1.1181 | F49: 4.0462 | G49: 1.8743 | H49: 3.299 | I49: 1.2651 | J49: 0.5912 | K49: 0.1849 | L49: 0.7324 | M49: 0.4147 | N49: 0.0577 | O49: 2.3426 | P49: 0.2385 | Q49: 0.5698 | R49: 0.3098 | S49: 31.9715 | T49: =S49 -> 31.9715
A50: 44105 | B50: 14.4634 | C50: 3.3129 | D50: =SUM(F50:O50) -> 14.0293 | E50: =S50-B50-C50-D50 -> 1.0648 | F50: 4.6207 | G50: 2.2118 | H50: 1.7563 | I50: 1.0216 | J50: 0.6092 | K50: 0.2068 | L50: 0.8164 | M50: 0.4646 | N50: 0.0171 | O50: 2.3048 | P50: 0.1881 | Q50: 0.4995 | R50: 0.3772 | S50: 32.8704 | T50: =T49+S50 -> 64.8419
A51: 44136 | B51: 18.3269 | C51: 3.3271 | D51: =SUM(F51:O51) -> 14.4721 | E51: =S51-B51-C51-D51 -> 0.976 | F51: 5.7544 | G51: 1.9028 | H51: 1.8166 | I51: 0.9992 | J51: 0.6842 | K51: 0.2412 | L51: 0.9201 | M51: 0.1543 | N51: 0.0196 | O51: 1.9797 | P51: 0.2333 | Q51: 0.3951 | R51: 0.3476 | S51: 37.1021 | T51: =S51 -> 37.1021
A52: 44166 | B52: 20.6728 | C52: 4.3614 | D52: =SUM(F52:O52) -> 24.0164 | E52: =S52-B52-C52-D52 -> 1.1979 | F52: 7.9806 | G52: 3.6664 | H52: 3.0653 | I52: 1.7753 | J52: 0.6756 | K52: 0.3123 | L52: 2.7541 | M52: 0.2804 | N52: 0.0732 | O52: 3.4332 | P52: 0.3657 | Q52: 0.512 | R52: 0.3202 | S52: 50.2485 | T52: =T51+S52 -> 87.3506
A53: 44197 | B53: 16.201 | C53: 3.5805 | D53: =SUM(F53:O53) -> 10.924 | E53: =S53-B53-C53-D53 -> 0.766 | F53: 3.5962 | G53: 1.49 | H53: 1.2459 | I53: 0.8229 | J53: 0.9209 | K53: 0.1435 | L53: 0.4394 | M53: 0.2776 | N53: 0.1893 | O53: 1.7983 | P53: 0.3117 | Q53: 0.1662 | R53: 0.2881 | S53: 31.4715 | T53: =S53 -> 31.4715
A54: 44228 | B54: 9.7959 | C54: 3.9277 | D54: =SUM(F54:O54) -> 11.2794 | E54: =S54-B54-C54-D54 -> 1.2353 | F54: 3.862 | G54: 1.787 | H54: 0.6803 | I54: 0.8391 | J54: 1.1192 | K54: 0.1497 | L54: 0.284 | M54: 0.3975 | N54: 0.1989 | O54: 1.9617 | P54: 0.3783 | Q54: 0.557 | R54: 0.3 | S54: 26.2383 | T54: =T53+S54 -> 57.7098
...

Sheet 全球新能源车分车型销量
A5: 全球新能源乘用车销量(辆)
A6: 车型 | B6: 43101 | C6: 43132 | D6: 43160 | E6: 43191 | F6: 43221 | G6: 43252 | H6: 43282 | I6: 43313 | J6: 43344 | K6: 43374 | L6: 43405 | M6: 43435 | N6: 43466 | O6: 43497 | P6: 43525 | Q6: 43556 | R6: 43586 | S6: 43617 | T6: 43647 | U6: 43678 | V6: 43709 | W6: 43739 | X6: 43770 | Y6: 43800 | Z6: 43831 | AA6: 43862 | AB6: 43891 | AC6: 43922 | AD6: 43952 | AE6: 43983 | AF6: 44013 | AG6: 44044 | AH6: 44075 | AI6: 44105 | AJ6: 44136 | AK6: 44166 | AL6: 44197 | AM6: 44228 | AN6: 44256 | AO6: 44287 | AP6: 44317 | AQ6: 44348 | AR6: 44378 | AS6: 44409 | AT6: 44440 | AU6: 44470 | AV6: 44501 | AW6: 44531 | AX6: 44562 | AY6: 44593 | AZ6: 44621 | BA6: 44652 | BB6: 44682 | BC6: 44713 | BD6: 44743 | BE6: 44774 | BF6: 44805 | BG6: 44835 | BH6: 44866 | BI6: 44896 | BJ6: 44927 | BK6: 44958 | BL6: 44986 | BM6: 45017 | BN6: 45047 | BO6: 45078 | BP6: 45108 | BQ6: 45139 | BR6: 45170 | BS6: 45200 | BT6: 45231 | BU6: 45262 | BV6: 45293 | BW6: 45324 | BX6: 同比 | BY6: 环比 | BZ6: 2018 | CA6: 2019 | CB6: 2020 | CC6: 2021 | CD6: 2022 | CE6: 2023 | CF6: 2024
A7: Model Y | AB7: 1009 | AC7: 203 | AD7: 303 | AE7: 1506 | AF7: 6540 | AG7: 9050 | AH7: 11467 | AI7: 11082 | AJ7: 12961 | AK7: 16404 | AL7: 17062 | AM7: 14956 | AN7: 25027 | AO7: 12766 | AP7: 28256 | AQ7: 24956 | AR7: 25534 | AS7: 35017 | AT7: 66074 | AU7: 46746 | AV7: 58455 | AW7: 77610 | AX7: 55056 | AY7: 60748 | AZ7: 84697 | BA7: 28631 | BB7: 45062 | BC7: 90178 | BD7: 38862 | BE7: 91436 | BF7: 106969 | BG7: 67344 | BH7: 112048 | BI7: 90056 | BJ7: 52753 | BK7: 80152 | BL7: 140654 | BM7: 74295 | BN7: 91973 | BO7: 130187 | BP7: 75454 | BQ7: 127078 | BR7: 125293 | BS7: 93239 | BT7: 114311 | BU7: 127685 | BV7: 58455 | BW7: 77610 | BX7: =IF(ISERROR(BW7/BK7-1),"",BW7/BK7-1) -> -0.031714742 | BY7: =IF(ISERROR(BW7/BV7-1),"",BW7/BV7-1) -> 0.32768797 | BZ7: =SUM(B7:M7) -> 0 | CA7: =SUM(N7:Y7) -> 0 | CB7: =SUM(Z7:AK7) -> 70525 | CC7: =SUM(AL7:AW7) -> 432459 | CD7: =SUM(AX7:BI7) -> 871087 | CE7: =SUM(BJ7:BU7) -> 1233074 | CF7: =SUM(BV7:BW7) -> 136065
A8: 五菱宏光mini EV | AF8: 7348 | AG8: 15000 | AH8: 20150 | AI8: 23762 | AJ8: 28246 | AK8: 32097 | AL8: 36762 | AM8: 20167 | AN8: 39745 | AO8: 29251 | AP8: 26742 | AQ8: 30100 | AR8: 26907 | AS8: 41188 | AT8: 35176 | AU8: 39128 | AV8: 45576 | AW8: 55742 | AX8: 37048 | AY8: 22110 | AZ8: 47563 | BA8: 27181 | BB8: 34037 | BC8: 46249 | BD8: 56605 | BE8: 49119 | BF8: 44711 | BG8: 47868 | BH8: 68567 | BI8: 73009 | BJ8: 16416 | BK8: 30267 | BL8: 23159 | BM8: 18086 | BN8: 20346 | BO8: 13763 | BP8: 15499 | BQ8: 2068 | BR8: 287 | BS8: 8367 | BT8: 24027 | BU8: 50561 | BV8: 45576 | BW8: 55742 | BX8: =IF(ISERROR(BW8/BK8-1),"",BW8/BK8-1) -> 0.84167575 | BY8: =IF(ISERROR(BW8/BV8-1),"",BW8/BV8-1) -> 0.22305599 | BZ8: =SUM(B8:M8) -> 0 | CA8: =SUM(N8:Y8) -> 0 | CB8: =SUM(Z8:AK8) -> 126603 | CC8: =SUM(AL8:AW8) -> 426484 | CD8: =SUM(AX8:BI8) -> 554067 | CE8: =SUM(BJ8:BU8) -> 222846 | CF8: =SUM(BV8:BW8) -> 101318
A9: Model 3 | B9: 1900 | C9: 2600 | D9: 3680 | E9: 3800 | F9: 6311 | G9: 5550 | H9: 15540 | I9: 17500 | J9: 24000 | K9: 18600 | L9: 19800 | M9: 25004 | N9: 17261 | O9: 17995 | P9: 26700 | Q9: 12753 | R9: 12063 | S9: 22877 | T9: 15260 | U9: 16551 | V9: 31104 | W9: 15718 | X9: 21944 | Y9: 42156 | Z9: 22516 | AA9: 24589 | AB9: 36580 | AC9: 11467 | AD9: 20462 | AE9: 30876 | AF9: 20709 | AG9: 28699 | AH9: 35892 | AI9: 23083 | AJ9: 36054 | AK9: 58535 | AL9: 25248 | AM9: 24794 | AN9: 58716 | AO9: 32267 | AP9: 41477 | AQ9: 61046 | AR9: 35600 | AS9: 45661 | AT9: 57123 | AU9: 43574 | AV9: 50900 | AW9: 74591 | AX9: 43453 | AY9: 51351 | AZ9: 75178 | BA9: 22039 | BB9: 33296 | BC9: 54010 | BD9: 32782 | BE9: 41558 | BF9: 68089 | BG9: 53505 | BH9: 67913 | BI9: 62686 | BJ9: 37909 | BK9: 39404 | BL9: 59834 | BM9: 37968 | BN9: 40361 | BO9: 61864 | BP9: 35395 | BQ9: 53081 | BR9: 47822 | BS9: 52903 | BT9: 62566 | BU9: 68600 | BV9: 50900 | BW9: 74591 | BX9: =IF(ISERROR(BW9/BK9-1),"",BW9/BK9-1) -> 0.89298041 | BY9: =IF(ISERROR(BW9/BV9-1),"",BW9/BV9-1) -> 0.46544204 | BZ9: =SUM(B9:M9) -> 144285 | CA9: =SUM(N9:Y9) -> 252382 | CB9: =SUM(Z9:AK9) -> 349462 | CC9: =SUM(AL9:AW9) -> 550997 | CD9: =SUM(AX9:BI9) -> 605860 | CE9: =SUM(BJ9:BU9) -> 597707 | CF9: =SUM(BV9:BW9) -> 125491
A10: 海豚 | AS10: 1755 | AT10: 3000 | AU10: 6018 | AV10: 8809 | AW10: 10016 | AX10: 10602 | AY10: 8565 | AZ10: 10501 | BA10: 12040 | BB10: 6430 | BC10: 10376 | BD10: 21005 | BE10: 23469 | BF10: 24956 | BG10: 25336 | BH10: 26063 | BI10: 26074 | BJ10: 17629 | BK10: 22861 | BL10: 30077 | BM10: 30462 | BN10: 30679 | BO10: 31140 | BP10: 31950 | BQ10: 32745 | BR10: 32927 | BS10: 35189 | BT10: 35246 | BU10: 36514 | BV10: 8809 | BW10: 10016 | BX10: =IF(ISERROR(BW10/BK10-1),"",BW10/BK10-1) -> -0.56187393 | BY10: =IF(ISERROR(BW10/BV10-1),"",BW10/BV10-1) -> 0.13701896 | BZ10: =SUM(B10:M10) -> 0 | CA10: =SUM(N10:Y10) -> 0 | CB10: =SUM(Z10:AK10) -> 0 | CC10: =SUM(AL10:AW10) -> 29598 | CD10: =SUM(AX10:BI10) -> 205417 | CE10: =SUM(BJ10:BU10) -> 367419 | CF10: =SUM(BV10:BW10) -> 18825
A11: 比亚迪元PLUS EV | AX11: 2000 | AY11: 4517 | AZ11: 10025 | BA11: 10100 | BB11: 11500 | BC11: 16704 | BD11: 19719 | BE11: 18006 | BF11: 23069 | BG11: 27611 | BH11: 30509 | BI11: 32629 | BJ11: 24777 | BK11: 36782 | BL11: 44250 | BM11: 42393 | BN11: 35521 | BO11: 35668 | BP11: 34402 | BQ11: 36425 | BR11: 37013 | BS11: 44515 | BT11: 45223 | BU11: 45587 | BV11: 0 | BW11: 0 | BX11: =IF(ISERROR(BW11/BK11-1),"",BW11/BK11-1) -> -1 | BY11: =IF(ISERROR(BW11/BV11-1),"",BW11/BV11-1) | BZ11: =SUM(B11:M11) -> 0 | CA11: =SUM(N11:Y11) -> 0 | CB11: =SUM(Z11:AK11) -> 0 | CC11: =SUM(AL11:AW11) -> 0 | CD11: =SUM(AX11:BI11) -> 206389 | CE11: =SUM(BJ11:BU11) -> 462556 | CF11: =SUM(BV11:BW11) -> 0
A12: 比亚迪汉 | AF12: 1205 | AG12: 2400 | AH12: 3624 | AI12: 5055 | AJ12: 7482 | AK12: 9007 | AL12: 9298 | AM12: 4100 | AN12: 7956 | AO12: 5747 | AP12: 5763 | AQ12: 5815 | AR12: 5907 | AS12: 6198 | AT12: 7796 | AU12: 8287 | AV12: 10021 | AW12: 10301 | AX12: 10051 | AY12: 8942 | AZ12: 10178 | BA12: 10225 | BB12: 12684 | BC12: 12945 | BD12: 13106 | BE12: 13191 | BF12: 13230 | BG12: 13293 | BH12: 13429 | BI12: 13743 | BJ12: 5615 | BK12: 5751 | BL12: 6802 | BM12: 7809 | BN12: 10290 | BO12: 11108 | BP12: 11752 | BQ12: 10443 | BR12: 10467 | BS12: 9344 | BT12: 9467 | BU12: 8648 | BV12: 10021 | BW12: 10301 | BX12: =IF(ISERROR(BW12/BK12-1),"",BW12/BK12-1) -> 0.79116675 | BY12: =IF(ISERROR(BW12/BV12-1),"",BW12/BV12-1) -> 0.027941323 | BZ12: =SUM(B12:M12) -> 0 | CA12: =SUM(N12:Y12) -> 0 | CB12: =SUM(Z12:AK12) -> 28773 | CC12: =SUM(AL12:AW12) -> 87189 | CD12: =SUM(AX12:BI12) -> 145017 | CE12: =SUM(BJ12:BU12) -> 107496 | CF12: =SUM(BV12:BW12) -> 20322
A13: AionS | R13: 668 | S13: 2016 | T13: 3406 | U13: 3815 | V13: 4006 | W13: 4217 | X13: 5538 | Y13: 8460 | Z13: 2648 | AA13: 1433 | AB13: 2957 | AC13: 3586 | AD13: 3892 | AE13: 3695 | AF13: 3685 | AG13: 4071 | AH13: 4548 | AI13: 4630 | AJ13: 5084 | AK13: 5397 | AL13: 6092 | AM13: 2724 | AN13: 5738 | AO13: 5077 | AP13: 4905 | AQ13: Model Y | AR13: 5072 | AS13: 5238 | AT13: 7679 | AU13: 7819 | AV13: 7465 | AW13: 6409 | AX13: 7049 | AY13: 3380 | AZ13: 6798 | BA13: 3291 | BB13: 10503 | BC13: 8903 | BD13: 6864 | BE13: 11695 | BF13: 13522 | BG13: 14507 | BH13: 15323 | BI13: 13844 | BJ13: 4091 | BK13: 16827 | BL13: 26392 | BM13: 19569 | BN13: 25233 | BO13: 22487 | BP13: 22437 | BQ13: 22896 | BR13: 21546 | BS13: 11730 | BT13: 12195 | BU13: 15824 | BV13: 7465 | BW13: 6409 | BX13: =IF(ISERROR(BW13/BK13-1),"",BW13/BK13-1) -> -0.61912403 | BY13: =IF(ISERROR(BW13/BV13-1),"",BW13/BV13-1) -> -0.14146015 | BZ13: =SUM(B13:M13) -> 0 | CA13: =SUM(N13:Y13) -> 32126 | CB13: =SUM(Z13:AK13) -> 45626 | CC13: =SUM(AL13:AW13) -> 64218 | CD13: =SUM(AX13:BI13) -> 115679 | CE13: =SUM(BJ13:BU13) -> 221227 | CF13: =SUM(BV13:BW13) -> 13874
A14: 秦PLUS EV | AO14: 1561 | AP14: 3263 | AQ14: 4272 | AR14: 5523 | AS14: 7633 | AT14: 8396 | AU14: 8405 | AV14: 10097 | AW14: 7001 | AX14: 7086 | AY14: 8264 | AZ14: 8682 | BA14: 7827 | BB14: 6848 | BC14: 11269 | BD14: 11276 | BE14: 11447 | BF14: 11606 | BG14: 12189 | BH14: 12870 | BI14: 10569 | BJ14: 6503 | BK14: 8434 | BL14: 8679 | BM14: 8718 | BN14: 10816 | BO14: 11420 | BP14: 11455 | BQ14: 11654 | BR14: 11837 | BS14: 11876 | BT14: 11900 | BU14: 15200 | BV14: 10097 | BW14: 7001 | BX14: =IF(ISERROR(BW14/BK14-1),"",BW14/BK14-1) -> -0.16990752 | BY14: =IF(ISERROR(BW14/BV14-1),"",BW14/BV14-1) -> -0.30662573 | BZ14: =SUM(B14:M14) -> 0 | CA14: =SUM(N14:Y14) -> 0 | CB14: =SUM(Z14:AK14) -> 0 | CC14: =SUM(AL14:AW14) -> 56151 | CD14: =SUM(AX14:BI14) -> 119933 | CE14: =SUM(BJ14:BU14) -> 128492 | CF14: =SUM(BV14:BW14) -> 17098
A15: Aion Y | AO15: 2000 | AP15: 2203 | AQ15: 2233 | AR15: 3109 | AS15: 4124 | AT15: 5003 | AU15: 3384 | AV15: 6032 | AW15: 6020 | AX15: 6413 | AY15: 2986 | AZ15: 9501 | BA15: 5261 | BB15: 8289 | BC15: 11801 | BD15: 12530 | BE15: 11012 | BF15: 13408 | BG15: 12615 | BH15: 11560 | BI15: 14311 | BJ15: 4792 | BK15: 12996 | BL15: 13267 | BM15: 21065 | BN15: 19306 | BO15: 20583 | BP15: 17861 | BQ15: 18227 | BR15: 27496 | BS15: 27304 | BT15: 22640 | BU15: 24018 | BV15: 6032 | BW15: 6020 | BX15: =IF(ISERROR(BW15/BK15-1),"",BW15/BK15-1) -> -0.53678055 | BY15: =IF(ISERROR(BW15/BV15-1),"",BW15/BV15-1) -> -0.0019893899 | BZ15: =SUM(B15:M15) -> 0 | CA15: =SUM(N15:Y15) -> 0 | CB15: =SUM(Z15:AK15) -> 0 | CC15: =SUM(AL15:AW15) -> 34108 | CD15: =SUM(AX15:BI15) -> 119687 | CE15: =SUM(BJ15:BU15) -> 229555 | CF15: =SUM(BV15:BW15) -> 12052
A16: 长安Lumin | BD16: 7412 | BE16: 10783 | BF16: 11267 | BG16: 13235 | BH16: 13235 | BI16: 12468 | BJ16: 4711 | BK16: 9105 | BL16: 10217 | BM16: 7643 | BN16: 8491 | BO16: 10714 | BP16: 14103 | BQ16: 11788 | BR16: 14484 | BS16: 14417 | BT16: 14943 | BU16: 13537 | BV16: 0 | BW16: 0 | BX16: =IF(ISERROR(BW16/BK16-1),"",BW16/BK16-1) -> -1 | BY16: =IF(ISERROR(BW16/BV16-1),"",BW16/BV16-1) | BZ16: =SUM(B16:M16) -> 0 | CA16: =SUM(N16:Y16) -> 0 | CB16: =SUM(Z16:AK16) -> 0 | CC16: =SUM(AL16:AW16) -> 0 | CD16: =SUM(AX16:BI16) -> 68400 | CE16: =SUM(BJ16:BU16) -> 134153 | CF16: =SUM(BV16:BW16) -> 0
A17: 哪吒V | AJ17: 1337 | AK17: 1696 | AL17: 2076 | AM17: 2002 | AN17: 3206 | AO17: 3846 | AP17: 3409 | AQ17: 3533 | AR17: 4469 | AS17: 4611 | AT17: 5009 | AU17: 5178 | AV17: 7027 | AW17: 5280 | AX17: 6482 | AY17: 4073 | AZ17: 8122 | BA17: 5694 | BB17: 7884 | BC17: 9147 | BD17: 8967 | BE17: 10236 | BF17: 11935 | BG17: 11721 | BH17: 11283 | BI17: 3372 | BJ17: 4042 | BK17: 6267 | BL17: 5486 | BM17: 5291 | BN17: 5824 | BO17: 5672 | BP17: 3817 | BQ17: 6860 | BR17: 854 | BS17: 951 | BT17: 1234 | BU17: 1479 | BV17: 7027 | BW17: 5280 | BX17: =IF(ISERROR(BW17/BK17-1),"",BW17/BK17-1) -> -0.15749162 | BY17: =IF(ISERROR(BW17/BV17-1),"",BW17/BV17-1) -> -0.24861249 | BZ17: =SUM(B17:M17) -> 0 | CA17: =SUM(N17:Y17) -> 0 | CB17: =SUM(Z17:AK17) -> 3033 | CC17: =SUM(AL17:AW17) -> 49646 | CD17: =SUM(AX17:BI17) -> 98916 | CE17: =SUM(BJ17:BU17) -> 47777 | CF17: =SUM(BV17:BW17) -> 12307 | OV17: =VLOOKUP(A7,G:TT,27,FALSE) -> #N/A
A18: eQ1电动车 | B18: 1428 | C18: 2753 | D18: 3279 | E18: 3799 | F18: 3055 | G18: 4434 | H18: 3665 | I18: 4613 | J18: 5310 | K18: 5547 | L18: 4352 | M18: 4732 | N18: 3375 | O18: 3157 | P18: 2838 | Q18: 4129 | R18: 3818 | S18: 4965 | T18: 2405 | U18: 2345 | V18: 2584 | W18: 2414 | X18: 1861 | Y18: 5510 | Z18: 751 | AA18: 470 | AB18: 1073 | AC18: 2299 | AD18: 2563 | AE18: 2632 | AF18: 3056 | AG18: 3307 | AH18: 3823 | AI18: 4745 | AJ18: 6805 | AK18: 7074 | AL18: 6316 | AM18: 1591 | AN18: 5310 | AO18: 5617 | AP18: 5632 | AQ18: 6317 | AR18: 5565 | AS18: 5975 | AT18: 7815 | AU18: 7433 | AV18: 9291 | AW18: 10141 | AX18: 9412 | AY18: 3735 | AZ18: 8240 | BA18: 6086 | BB18: 9754 | BC18: 9692 | BD18: 11489 | BE18: 10037 | BF18: 9292 | BG18: 9940 | BH18: 4020 | BI18: 3972 | BJ18: 1035 | BK18: 2128 | BL18: 1872 | BM18: 2439 | BN18: 1429 | BO18: 1541 | BP18: 2110 | BQ18: 2324 | BR18: 2746 | BS18: 2426 | BT18: 3277 | BU18: 3523 | BV18: 9291 | BW18: 10141 | BX18: =IF(ISERROR(BW18/BK18-1),"",BW18/BK18-1) -> 3.7655075 | BY18: =IF(ISERROR(BW18/BV18-1),"",BW18/BV18-1) -> 0.091486385 | BZ18: =SUM(B18:M18) -> 46967 | CA18: =SUM(N18:Y18) -> 39401 | CB18: =SUM(Z18:AK18) -> 38598 | CC18: =SUM(AL18:AW18) -> 77003 | CD18: =SUM(AX18:BI18) -> 95669 | CE18: =SUM(BJ18:BU18) -> 26850 | CF18: =SUM(BV18:BW18) -> 19432 | OV18: =VLOOKUP(A7,G:TT,27) -> #N/A
A19: 欧拉好猫 | AK19: 2016 | AL19: 2081 | AM19: 1534 | AN19: 2116 | AO19: 1264 | AP19: 1277 | AQ19: 3405 | AR19: 2779 | AS19: 4005 | AT19: 5085 | AU19: 7845 | AV19: 8855 | AW19: 10685 | AX19: 9054 | AY19: 4209 | AZ19: 6700 | BA19: 1704 | BB19: 4265 | BC19: 8728 | BD19: 7525 | BE19: 8621 | BF19: 7690 | BG19: 5504 | BH19: 4132 | BI19: 4229 | BJ19: 1665 | BK19: 2733 | BL19: 4554 | BM19: 7335 | BN19: 8154 | BO19: 9011 | BP19: 8807 | BQ19: 12378 | BR19: 10574 | BS19: 10481 | BT19: 10540 | BU19: 10740 | BV19: 8855 | BW19: 10685 | BX19: =IF(ISERROR(BW19/BK19-1),"",BW19/BK19-1) -> 2.9096231 | BY19: =IF(ISERROR(BW19/BV19-1),"",BW19/BV19-1) -> 0.2066629 | BZ19: =SUM(B19:M19) -> 0 | CA19: =SUM(N19:Y19) -> 0 | CB19: =SUM(Z19:AK19) -> 2016 | CC19: =SUM(AL19:AW19) -> 50931 | CD19: =SUM(AX19:BI19) -> 72361 | CE19: =SUM(BJ19:BU19) -> 96972 | CF19: =SUM(BV19:BW19) -> 19540
A20: QQ冰淇淋 | AV20: 4289 | AW20: 8390 | AX20: 9984 | AY20: 6442 | AZ20: 11687 | BA20: 7078 | BB20: 9243 | BC20: 9663 | BD20: 9391 | BE20: 8616 | BF20: 8650 | BG20: 7145 | BH20: 4048 | BI20: 4592 | BJ20: 2736 | BK20: 3134 | BL20: 3951 | BM20: 4253 | BN20: 5358 | BO20: 6041 | BP20: 5716 | BQ20: 5845 | BR20: 7294 | BS20: 7318 | BT20: 9219 | BU20: 7462 | BV20: 4289 | BW20: 8390 | BX20: =IF(ISERROR(BW20/BK20-1),"",BW20/BK20-1) -> 1.67709 | BY20: =IF(ISERROR(BW20/BV20-1),"",BW20/BV20-1) -> 0.95616694 | BZ20: =SUM(B20:M20) -> 0 | CA20: =SUM(N20:Y20) -> 0 | CB20: =SUM(Z20:AK20) -> 0 | CC20: =SUM(AL20:AW20) -> 12679 | CD20: =SUM(AX20:BI20) -> 96539 | CE20: =SUM(BJ20:BU20) -> 68327 | CF20: =SUM(BV20:BW20) -> 12679
A21: ID.4 CROZZ | AM21: 180 | AN21: 365 | AO21: 722 | AP21: 502 | AQ21: 2191 | AR21: 1216 | AS21: 2993 | AT21: 3858 | AU21: 3235 | AV21: 5187 | AW21: 6404 | AX21: 2206 | AY21: 2374 | AZ21: 3177 | BA21: 2610 | BB21: 3460 | BC21: 6140 | BD21: 6270 | BE21: 8178 | BF21: 3570 | BG21: 3557 | BH21: 3038 | BI21: 4168 | BJ21: 532 | BK21: 1641 | BL21: 2260 | BM21: 1639 | BN21: 3937 | BO21: 3792 | BP21: 3190 | BQ21: 2588 | BR21: 4173 | BS21: 4270 | BT21: 4070 | BU21: 5408 | BV21: 5187 | BW21: 6404 | BX21: =IF(ISERROR(BW21/BK21-1),"",BW21/BK21-1) -> 2.9024985 | BY21: =IF(ISERROR(BW21/BV21-1),"",BW21/BV21-1) -> 0.23462502 | BZ21: =SUM(B21:M21) -> 0 | CA21: =SUM(N21:Y21) -> 0 | CB21: =SUM(Z21:AK21) -> 0 | CC21: =SUM(AL21:AW21) -> 26853 | CD21: =SUM(AX21:BI21) -> 48748 | CE21: =SUM(BJ21:BU21) -> 37500 | CF21: =SUM(BV21:BW21) -> 11591
A22: 大众ID.4 | AI22: 72 | AJ22: 22 | AK22: 4714 | AL22: 401 | AM22: 426 | AN22: 5438 | AO22: 8543 | AP22: 7100 | AQ22: 8929 | AR22: 6777 | AS22: 6579 | AT22: 5969 | AU22: 7049 | AV22: 5968 | AW22: 8555 | AX22: 4302 | AY22: 4166 | AZ22: 5816 | BA22: 3716 | BB22: 3357 | BC22: 5310 | BD22: 7707 | BE22: 7453 | BF22: 9150 | BG22: 9284 | BH22: 9876 | BI22: 18027 | BJ22: 6905 | BK22: 7958 | BL22: 10514 | BM22: 7504 | BN22: 10585 | BO22: 12611 | BP22: 11389 | BQ22: 11879 | BR22: 10496 | BS22: 9430 | BT22: 9828 | BU22: 12134 | BV22: 5968 | BW22: 8555 | BX22: =IF(ISERROR(BW22/BK22-1),"",BW22/BK22-1) -> 0.075018849 | BY22: =IF(ISERROR(BW22/BV22-1),"",BW22/BV22-1) -> 0.43347855 | BZ22: =SUM(B22:M22) -> 0 | CA22: =SUM(N22:Y22) -> 0 | CB22: =SUM(Z22:AK22) -> 4808 | CC22: =SUM(AL22:AW22) -> 71734 | CD22: =SUM(AX22:BI22) -> 88164 | CE22: =SUM(BJ22:BU22) -> 121233 | CF22: =SUM(BV22:BW22) -> 14523
A23: 风神E70 | B23: 561 | C23: 29 | D23: 507 | E23: 1102 | F23: 624 | G23: 340 | H23: 400 | I23: 263 | J23: 674 | K23: 855 | L23: 1395 | M23: 1937 | N23: 1282 | O23: 603 | P23: 1444 | Q23: 525 | R23: 1243 | S23: 3524 | T23: 148 | U23: 373 | V23: 331 | W23: 1121 | X23: 2552 | Y23: 1826 | Z23: 155 | AA23: 2 | AB23: 35 | AC23: 59 | AD23: 395 | AE23: 402 | AF23: 506 | AG23: 23 | AH23: 200 | AI23: 1331 | AJ23: 909 | AK23: 695 | AL23: 26 | AN23: 855 | AO23: 1035 | AP23: 2067 | AQ23: 3500 | AR23: 3120 | AS23: 2416 | AT23: 4771 | AU23: 4322 | AV23: 4690 | AW23: 3609 | AX23: 3053 | AY23: 2641 | AZ23: 4345 | BA23: 4306 | BB23: 4666 | BC23: 8193 | BD23: 7556 | BE23: 7410 | BF23: 8692 | BG23: 10032 | BH23: 6210 | BI23: 7368 | BJ23: 1323 | BK23: 956 | BL23: 639 | BM23: 3191 | BN23: 3089 | BO23: 3054 | BP23: 2923 | BQ23: 4279 | BR23: 3304 | BS23: 3140 | BT23: 3865 | BU23: 2223 | BV23: 4690 | BW23: 3609 | BX23: =IF(ISERROR(BW23/BK23-1),"",BW23/BK23-1) -> 2.7751046 | BY23: =IF(ISERROR(BW23/BV23-1),"",BW23/BV23-1) -> -0.23049041 | BZ23: =SUM(B23:M23) -> 8687 | CA23: =SUM(N23:Y23) -> 14972 | CB23: =SUM(Z23:AK23) -> 4712 | CC23: =SUM(AL23:AW23) -> 30411 | CD23: =SUM(AX23:BI23) -> 74472 | CE23: =SUM(BJ23:BU23) -> 31986 | CF23: =SUM(BV23:BW23) -> 8299
A24: 极氪001 | AU24: 199 | AV24: 2012 | AW24: 3796 | AX24: 3530 | AY24: 2916 | AZ24: 1795 | BA24: 2137 | BB24: 4330 | BC24: 4302 | BD24: 5022 | BE24: 7166 | BF24: 8276 | BG24: 10119 | BH24: 11011 | BI24: 11337 | BJ24: 3116 | BK24: 4839 | BL24: 4517 | BM24: 6463 | BN24: 6223 | BO24: 6147 | BP24: 6170 | BQ24: 6822 | BR24: 8701 | BS24: 8517 | BT24: 6751 | BU24: 7980 | BV24: 2012 | BW24: 3796 | BX24: =IF(ISERROR(BW24/BK24-1),"",BW24/BK24-1) -> -0.2155404 | BY24: =IF(ISERROR(BW24/BV24-1),"",BW24/BV24-1) -> 0.88667992 | BZ24: =SUM(B24:M24) -> 0 | CA24: =SUM(N24:Y24) -> 0 | CB24: =SUM(Z24:AK24) -> 0 | CC24: =SUM(AL24:AW24) -> 6007 | CD24: =SUM(AX24:BI24) -> 71941 | CE24: =SUM(BJ24:BU24) -> 76246 | CF24: =SUM(BV24:BW24) -> 5808
A25: 名爵EZS | Q25: 653 | R25: 1015 | S25: 248 | T25: 477 | U25: 1874 | V25: 1800 | W25: 2549 | X25: 3687 | Y25: 4718 | Z25: 2271 | AA25: 1029 | AB25: 4013 | AC25: 247 | AD25: 609 | AE25: 2039 | AF25: 3100 | AG25: 3251 | AH25: 5515 | AI25: 5602 | AJ25: 5370 | AK25: 5675 | AL25: 1679 | AM25: 1196 | AN25: 2540 | AO25: 1413 | AP25: 1516 | AQ25: 4028 | AR25: 1693 | AS25: 2991 | AT25: 4394 | AU25: 4023 | AV25: 4426 | AW25: 3997 | AX25: 2778 | AY25: 2997 | AZ25: 3718 | BA25: 2988 | BB25: 3289 | BC25: 6610 | BD25: 5295 | BE25: 6383 | BF25: 6660 | BG25: 7882 | BH25: 9824 | BI25: 11034 | BJ25: 6403 | BK25: 6731 | BL25: 14931 | BM25: 9744 | BN25: 11627 | BO25: 9644 | BP25: 4264 | BQ25: 5148 | BR25: 3946 | BS25: 3216 | BT25: 2966 | BU25: 5436 | BV25: 4426 | BW25: 3997 | BX25: =IF(ISERROR(BW25/BK25-1),"",BW25/BK25-1) -> -0.40618036 | BY25: =IF(ISERROR(BW25/BV25-1),"",BW25/BV25-1) -> -0.096927248 | BZ25: =SUM(B25:M25) -> 0 | CA25: =SUM(N25:Y25) -> 17021 | CB25: =SUM(Z25:AK25) -> 38721 | CC25: =SUM(AL25:AW25) -> 33896 | CD25: =SUM(AX25:BI25) -> 69458 | CE25: =SUM(BJ25:BU25) -> 84056 | CF25: =SUM(BV25:BW25) -> 8423
A26: 宝骏KiWi EV | AY26: 3262 | AZ26: 2707 | BA26: 2221 | BB26: 2967 | BC26: 2594 | BD26: 2276 | BE26: 6330 | BF26: 3116 | BG26: 2539 | BH26: 2374 | BI26: 2422 | BJ26: 482 | BK26: 771 | BL26: 627 | BM26: 380 | BN26: 290 | BO26: 274 | BP26: 333 | BQ26: 14 | BR26: 1225 | BS26: 0 | BT26: 15 | BU26: 0 | BV26: 0 | BW26: 0 | BX26: =IF(ISERROR(BW26/BK26-1),"",BW26/BK26-1) -> -1 | BY26: =IF(ISERROR(BW26/BV26-1),"",BW26/BV26-1) | BZ26: =SUM(B26:M26) -> 0 | CA26: =SUM(N26:Y26) -> 0 | CB26: =SUM(Z26:AK26) -> 0 | CC26: =SUM(AL26:AW26) -> 0 | CD26: =SUM(AX26:BI26) -> 32808 | CE26: =SUM(BJ26:BU26) -> 4411 | CF26: =SUM(BV26:BW26) -> 0
A27: 几何E | BC27: 4033 | BD27: 5171 | BE27: 6320 | BF27: 5714 | BG27: 1496 | BH27: 2271 | BI27: 4357 | BJ27: 1522 | BK27: 1838 | BL27: 1092 | BM27: 2632 | BN27: 1493 | BO27: 1470 | BP27: 1591 | BQ27: 3541 | BR27: 4547 | BS27: 4578 | BT27: 4375 | BU27: 4228 | BV27: 0 | BW27: 0 | BX27: =IF(ISERROR(BW27/BK27-1),"",BW27/BK27-1) -> -1 | BY27: =IF(ISERROR(BW27/BV27-1),"",BW27/BV27-1) | BZ27: =SUM(B27:M27) -> 0 | CA27: =SUM(N27:Y27) -> 0 | CB27: =SUM(Z27:AK27) -> 0 | CC27: =SUM(AL27:AW27) -> 0 | CD27: =SUM(AX27:BI27) -> 29362 | CE27: =SUM(BJ27:BU27) -> 32907 | CF27: =SUM(BV27:BW27) -> 0
A28: 零跑C11 | AT28: 294 | AU28: 163 | AV28: 1422 | AW28: 2164 | AX28: 2069 | AY28: 1521 | AZ28: 4201 | BA28: 1931 | BB28: 4345 | BC28: 4848 | BD28: 6582 | BE28: 6277 | BF28: 4398 | BG28: 2159 | BH28: 2720 | BI28: 3320 | BJ28: 426 | BK28: 1712 | BL28: 3154 | BM28: 6146 | BN28: 7121 | BO28: 8934 | BP28: 9283 | BQ28: 10024 | BR28: 8071 | BS28: 6330 | BT28: 3163 | BU28: 0 | BV28: 0 | BW28: 0 | BX28: =IF(ISERROR(BW28/BK28-1),"",BW28/BK28-1) -> -1 | BY28: =IF(ISERROR(BW28/BV28-1),"",BW28/BV28-1) | BZ28: =SUM(B28:M28) -> 0 | CA28: =SUM(N28:Y28) -> 0 | CB28: =SUM(Z28:AK28) -> 0 | CC28: =SUM(AL28:AW28) -> 4043 | CD28: =SUM(AX28:BI28) -> 44371 | CE28: =SUM(BJ28:BU28) -> 64364 | CF28: =SUM(BV28:BW28) -> 0
A29: 零跑T03 | AE29: 698 | AF29: 739 | AG29: 815 | AH29: 990 | AI29: 1681 | AJ29: 1927 | AK29: 2981 | AL29: 1637 | AM29: 371 | AN29: 2827 | AO29: 2729 | AP29: 3147 | AQ29: 3745 | AR29: 4283 | AS29: 4409 | AT29: 3807 | AU29: 3486 | AV29: 4177 | AW29: 5627 | AX29: 6007 | AY29: 1907 | AZ29: 5853 | BA29: 7156 | BB29: 5724 | BC29: 6411 | BD29: 5462 | BE29: 6248 | BF29: 6088 | BG29: 3564 | BH29: 3570 | BI29: 3937 | BJ29: 502 | BK29: 1332 | BL29: 2119 | BM29: 1580 | BN29: 2097 | BO29: 1664 | BP29: 2205 | BQ29: 2099 | BR29: 4494 | BS29: 6424 | BT29: 7599 | BU29: 7191 | BV29: 4177 | BW29: 5627 | BX29: =IF(ISERROR(BW29/BK29-1),"",BW29/BK29-1) -> 3.2244745 | BY29: =IF(ISERROR(BW29/BV29-1),"",BW29/BV29-1) -> 0.3471391 | BZ29: =SUM(B29:M29) -> 0 | CA29: =SUM(N29:Y29) -> 0 | CB29: =SUM(Z29:AK29) -> 9831 | CC29: =SUM(AL29:AW29) -> 40245 | CD29: =SUM(AX29:BI29) -> 61927 | CE29: =SUM(BJ29:BU29) -> 39306 | CF29: =SUM(BV29:BW29) -> 9804
A30: IONIQ 5 | AO30: 114 | AP30: 2157 | AQ30: 4789 | AR30: 5329 | AS30: 5548 | AT30: 6548 | AU30: 7166 | AV30: 6223 | AW30: 6564 | AX30: 5380 | AY30: 10588 | AZ30: 9757 | BA30: 8788 | BB30: 8245 | BC30: 7507 | BD30: 8348 | BE30: 6177 | BF30: 7318 | BG30: 7052 | BH30: 7493 | BI30: 8448 | BJ30: 4757 | BK30: 7390 | BL30: 7843 | BM30: 7985 | BN30: 8381 | BO30: 8753 | BP30: 9304 | BQ30: 9105 | BR30: 8403 | BS30: 8541 | BT30: 8097 | BU30: 7531 | BV30: 6223 | BW30: 6564 | BX30: =IF(ISERROR(BW30/BK30-1),"",BW30/BK30-1) -> -0.11177267 | BY30: =IF(ISERROR(BW30/BV30-1),"",BW30/BV30-1) -> 0.054796722 | BZ30: =SUM(B30:M30) -> 0 | CA30: =SUM(N30:Y30) -> 0 | CB30: =SUM(Z30:AK30) -> 0 | CC30: =SUM(AL30:AW30) -> 44438 | CD30: =SUM(AX30:BI30) -> 95101 | CE30: =SUM(BJ30:BU30) -> 96090 | CF30: =SUM(BV30:BW30) -> 12787
A31: 起亚EV6 | AS31: 1911 | AT31: 2757 | AU31: 4838 | AV31: 4824 | AW31: 4575 | AX31: 3180 | AY31: 6027 | AZ31: 9047 | BA31: 8509 | BB31: 7544 | BC31: 6560 | BD31: 6993 | BE31: 6005 | BF31: 6180 | BG31: 5605 | BH31: 5021 | BI31: 5717 | BJ31: 2995 | BK31: 5099 | BL31: 8080 | BM31: 7100 | BN31: 7365 | BO31: 7148 | BP31: 7325 | BQ31: 8484 | BR31: 6659 | BS31: 6388 | BT31: 5157 | BU31: 4447 | BV31: 4824 | BW31: 4575 | BX31: =IF(ISERROR(BW31/BK31-1),"",BW31/BK31-1) -> -0.10276525 | BY31: =IF(ISERROR(BW31/BV31-1),"",BW31/BV31-1) -> -0.051616915 | BZ31: =SUM(B31:M31) -> 0 | CA31: =SUM(N31:Y31) -> 0 | CB31: =SUM(Z31:AK31) -> 0 | CC31: =SUM(AL31:AW31) -> 18905 | CD31: =SUM(AX31:BI31) -> 76388 | CE31: =SUM(BJ31:BU31) -> 76247 | CF31: =SUM(BV31:BW31) -> 9399
A32: Mustang Mach-E | AK32: 242 | AL32: 286 | AM32: 4016 | AN32: 2981 | AO32: 2551 | AP32: 4595 | AQ32: 6083 | AR32: 6757 | AS32: 5481 | AT32: 4836 | AU32: 4654 | AV32: 6235 | AW32: 6167 | AX32: 5010 | AY32: 3867 | AZ32: 5007 | BA32: 6216 | BB32: 7842 | BC32: 4776 | BD32: 9376 | BE32: 5954 | BF32: 4748 | BG32: 6164 | BH32: 6450 | BI32: 10169 | BJ32: 3763 | BK32: 2680 | BL32: 3363 | BM32: 3145 | BN32: 4769 | BO32: 7415 | BP32: 6647 | BQ32: 8191 | BR32: 9185 | BS32: 5470 | BT32: 6713 | BU32: 8272 | BV32: 6235 | BW32: 6167 | BX32: =IF(ISERROR(BW32/BK32-1),"",BW32/BK32-1) -> 1.3011194 | BY32: =IF(ISERROR(BW32/BV32-1),"",BW32/BV32-1) -> -0.010906175 | BZ32: =SUM(B32:M32) -> 0 | CA32: =SUM(N32:Y32) -> 0 | CB32: =SUM(Z32:AK32) -> 242 | CC32: =SUM(AL32:AW32) -> 54642 | CD32: =SUM(AX32:BI32) -> 75579 | CE32: =SUM(BJ32:BU32) -> 69613 | CF32: =SUM(BV32:BW32) -> 12402
A33: 几何A | Q33: 1017 | R33: 1375 | S33: 1743 | T33: 1076 | U33: 1176 | V33: 1184 | W33: 1565 | X33: 2456 | Y33: 1070 | Z33: 96 | AA33: 285 | AB33: 293 | AC33: 168 | AD33: 216 | AE33: 63 | AF33: 874 | AG33: 326 | AH33: 464 | AI33: 725 | AJ33: 948 | AK33: 593 | AL33: 75 | AN33: 25 | AO33: 284 | AP33: 772 | AQ33: 942 | AR33: 1291 | AS33: 1639 | AT33: 1676 | AU33: 2004 | AV33: 2072 | AW33: 4206 | AX33: 3585 | AY33: 2192 | AZ33: 2450 | BA33: 2513 | BB33: 4461 | BC33: 4744 | BD33: 5286 | BE33: 5895 | BF33: 6307 | BG33: 5701 | BH33: 4922 | BI33: 5305 | BJ33: 1563 | BK33: 2248 | BL33: 2479 | BM33: 3039 | BN33: 1894 | BO33: 1049 | BP33: 1121 | BQ33: 2106 | BR33: 1154 | BS33: 802 | BT33: 479 | BU33: 547 | BV33: 2072 | BW33: 4206 | BX33: =IF(ISERROR(BW33/BK33-1),"",BW33/BK33-1) -> 0.87099644 | BY33: =IF(ISERROR(BW33/BV33-1),"",BW33/BV33-1) -> 1.0299228 | BZ33: =SUM(B33:M33) -> 0 | CA33: =SUM(N33:Y33) -> 12662 | CB33: =SUM(Z33:AK33) -> 5051 | CC33: =SUM(AL33:AW33) -> 14986 | CD33: =SUM(AX33:BI33) -> 53361 | CE33: =SUM(BJ33:BU33) -> 18481 | CF33: =SUM(BV33:BW33) -> 6278
A34: 荣威科莱威 | AB34: 97 | AC34: 566 | AD34: 531 | AE34: 2316 | AF34: 546 | AG34: 1 | AH34: 1880 | AI34: 3054 | AJ34: 467 | AK34: 2213 | AL34: 4675 | AM34: 13 | AN34: 2486 | AO34: 4130 | AP34: 4431 | AQ34: 2958 | AR34: 6183 | AS34: 8913 | AT34: 1209 | AU34: 9151 | AV34: 149 | AW34: 2539 | AX34: 5746 | AY34: 2085 | AZ34: 2269 | BA34: 1339 | BB34: 6263 | BC34: 4499 | BD34: 4678 | BE34: 5787 | BF34: 2506 | BG34: 3114 | BH34: 3914 | BI34: 2978 | BJ34: 0 | BK34: 1884 | BL34: 3493 | BM34: 3474 | BN34: 4048 | BO34: 4537 | BP34: 1949 | BQ34: 619 | BR34: 6 | BS34: 4 | BT34: 0 | BU34: 0 | BV34: 149 | BW34: 2539 | BX34: =IF(ISERROR(BW34/BK34-1),"",BW34/BK34-1) -> 0.34766454 | BY34: =IF(ISERROR(BW34/BV34-1),"",BW34/BV34-1) -> 16.040268 | BZ34: =SUM(B34:M34) -> 0 | CA34: =SUM(N34:Y34) -> 0 | CB34: =SUM(Z34:AK34) -> 11671 | CC34: =SUM(AL34:AW34) -> 46837 | CD34: =SUM(AX34:BI34) -> 45178 | CE34: =SUM(BJ34:BU34) -> 20014 | CF34: =SUM(BV34:BW34) -> 2688
A35: 哪吒U | AC35: 206 | AD35: 151 | AE35: 510 | AF35: 818 | AG35: 728 | AH35: 691 | AI35: 765 | AJ35: 603 | AK35: 776 | AL35: 119 | AN35: 40 | AO35: 169 | AP35: 1099 | AQ35: 1605 | AR35: 1542 | AS35: 2002 | AT35: 2690 | AU35: 2929 | AV35: 2986 | AW35: 4847 | AX35: 4527 | AY35: 3044 | AZ35: 3904 | BA35: 3119 | BB35: 3125 | BC35: 4010 | BD35: 5070 | BE35: 5781 | BF35: 6070 | BG35: 6295 | BH35: 3607 | BI35: 2469 | BJ35: 1012 | BK35: 3012 | BL35: 3056 | BM35: 3821 | BN35: 3963 | BO35: 5620 | BP35: 3433 | BQ35: 3617 | BR35: 3816 | BS35: 3967 | BT35: 0 | BU35: 0 | BV35: 2986 | BW35: 4847 | BX35: =IF(ISERROR(BW35/BK35-1),"",BW35/BK35-1) -> 0.60922975 | BY35: =IF(ISERROR(BW35/BV35-1),"",BW35/BV35-1) -> 0.6232418 | BZ35: =SUM(B35:M35) -> 0 | CA35: =SUM(N35:Y35) -> 0 | CB35: =SUM(Z35:AK35) -> 5248 | CC35: =SUM(AL35:AW35) -> 20028 | CD35: =SUM(AX35:BI35) -> 51021 | CE35: =SUM(BJ35:BU35) -> 35317 | CF35: =SUM(BV35:BW35) -> 7833
A36: 小鹏P7 | AE36: 302 | AF36: 1725 | AG36: 1996 | AH36: 2573 | AI36: 2104 | AJ36: 2732 | AK36: 3691 | AL36: 3710 | AM36: 1409 | AN36: 2855 | AO36: 2995 | AP36: 3797 | AQ36: 4730 | AR36: 6054 | AS36: 6165 | AT36: 7512 | AU36: 6044 | AV36: 7839 | AW36: 7459 | AX36: 6725 | AY36: 3634 | AZ36: 9195 | BA36: 3733 | BB36: 4237 | BC36: 8066 | BD36: 6410 | BE36: 5772 | BF36: 4651 | BG36: 2115 | BH36: 1815 | BI36: 3080 | BJ36: 1022 | BK36: 2294 | BL36: 3040 | BM36: 4068 | BN36: 4441 | BO36: 5198 | BP36: 5014 | BQ36: 4484 | BR36: 5365 | BS36: 4291 | BT36: 3107 | BU36: 4308 | BV36: 7839 | BW36: 7459 | BX36: =IF(ISERROR(BW36/BK36-1),"",BW36/BK36-1) -> 2.2515257 | BY36: =IF(ISERROR(BW36/BV36-1),"",BW36/BV36-1) -> -0.048475571 | BZ36: =SUM(B36:M36) -> 0 | CA36: =SUM(N36:Y36) -> 0 | CB36: =SUM(Z36:AK36) -> 15123 | CC36: =SUM(AL36:AW36) -> 60569 | CD36: =SUM(AX36:BI36) -> 59433 | CE36: =SUM(BJ36:BU36) -> 46632 | CF36: =SUM(BV36:BW36) -> 15298
A37: 比亚迪宋Pro EV | T37: 99 | U37: 454 | V37: 752 | W37: 765 | X37: 479 | Y37: 665 | Z37: 502 | AA37: 177 | AB37: 1003 | AC37: 1012 | AD37: 1015 | AE37: 1086 | AF37: 1198 | AG37: 849 | AH37: 859 | AI37: 1023 | AJ37: 1064 | AK37: 1044 | AL37: 135 | AM37: 62 | AN37: 182 | AO37: 1422 | AP37: 1619 | AQ37: 1985 | AR37: 2605 | AS37: 3579 | AT37: 4502 | AU37: 4588 | AV37: 4609 | AW37: 4052 | AY37: 3699 | AZ37: 4348 | BA37: 4927 | BB37: 5529 | BC37: 5560 | BD37: 5625 | BE37: 5688 | BF37: 5951 | BG37: 6066 | BH37: 6999 | BI37: 8391 | BJ37: 7181 | BK37: 7222 | BL37: 6704 | BM37: 4600 | BN37: 1031 | BO37: 2203 | BP37: 8408 | BQ37: 10240 | BR37: 10072 | BS37: 10982 | BT37: 11079 | BU37: 14100 | BV37: 4609 | BW37: 4052 | BX37: =IF(ISERROR(BW37/BK37-1),"",BW37/BK37-1) -> -0.43893658 | BY37: =IF(ISERROR(BW37/BV37-1),"",BW37/BV37-1) -> -0.12085051 | BZ37: =SUM(B37:M37) -> 0 | CA37: =SUM(N37:Y37) -> 3214 | CB37: =SUM(Z37:AK37) -> 10832 | CC37: =SUM(AL37:AW37) -> 29340 | CD37: =SUM(AX37:BI37) -> 62783 | CE37: =SUM(BJ37:BU37) -> 93822 | CF37: =SUM(BV37:BW37) -> 8661
A38: 大众ID.3 | AF38: 104 | AG38: 389 | AH38: 8287 | AI38: 10701 | AJ38: 8414 | AK38: 27955 | AL38: 2907 | AM38: 3701 | AN38: 4947 | AO38: 5866 | AP38: 6108 | AQ38: 7053 | AR38: 5496 | AS38: 7927 | AT38: 8316 | AU38: 6967 | AV38: 7561 | AW38: 8516 | AX38: 4967 | AY38: 3240 | AZ38: 4661 | BA38: 1867 | BB38: 4716 | BC38: 7381 | BD38: 8245 | BE38: 5557 | BF38: 5627 | BG38: 7486 | BH38: 10440 | BI38: 15029 | BJ38: 4866 | BK38: 6340 | BL38: 11598 | BM38: 9362 | BN38: 8101 | BO38: 8190 | BP38: 11539 | BQ38: 15555 | BR38: 13960 | BS38: 14600 | BT38: 19453 | BU38: 20691 | BV38: 7561 | BW38: 8516 | BX38: =IF(ISERROR(BW38/BK38-1),"",BW38/BK38-1) -> 0.34321767 | BY38: =IF(ISERROR(BW38/BV38-1),"",BW38/BV38-1) -> 0.12630604 | BZ38: =SUM(B38:M38) -> 0 | CA38: =SUM(N38:Y38) -> 0 | CB38: =SUM(Z38:AK38) -> 55850 | CC38: =SUM(AL38:AW38) -> 75365 | CD38: =SUM(AX38:BI38) -> 79216 | CE38: =SUM(BJ38:BU38) -> 144255 | CF38: =SUM(BV38:BW38) -> 16077
A39: 思皓E10X | AM39: 524 | AN39: 1619 | AO39: 2249 | AP39: 2257 | AQ39: 2801 | AR39: 2788 | AS39: 3255 | AT39: 4290 | AU39: 5322 | AV39: 5456 | AW39: 5578 | AX39: 4538 | AY39: 3550 | AZ39: 4023 | BA39: 3354 | BB39: 4950 | BC39: 4848 | BD39: 3908 | BE39: 5547 | BF39: 6005 | BG39: 4210 | BH39: 1642 | BI39: 3855 | BJ39: 841 | BK39: 1121 | BL39: 1049 | BM39: 1749 | BN39: 2169 | BO39: 1006 | BP39: 611 | BQ39: 830 | BR39: 1314 | BS39: 505 | BT39: 638 | BU39: 704 | BV39: 5456 | BW39: 5578 | BX39: =IF(ISERROR(BW39/BK39-1),"",BW39/BK39-1) -> 3.9759144 | BY39: =IF(ISERROR(BW39/BV39-1),"",BW39/BV39-1) -> 0.022360704 | BZ39: =SUM(B39:M39) -> 0 | CA39: =SUM(N39:Y39) -> 0 | CB39: =SUM(Z39:AK39) -> 0 | CC39: =SUM(AL39:AW39) -> 36139 | CD39: =SUM(AX39:BI39) -> 50430 | CE39: =SUM(BJ39:BU39) -> 12537 | CF39: =SUM(BV39:BW39) -> 11034
A40: 东风新能源EX1 | AU40: 5682 | AV40: 6131 | AW40: 8936 | AX40: 7947 | AY40: 6210 | AZ40: 4832 | BA40: 4294 | BB40: 7146 | BC40: 8176 | BD40: 8678 | BE40: 5476 | BF40: 4231 | BG40: 10785 | BH40: 5243 | BI40: 7546 | BJ40: 3082 | BK40: 4417 | BL40: 1587 | BM40: 847 | BN40: 0 | BO40: 0 | BP40: 0 | BQ40: 3281 | BR40: 4028 | BS40: 0 | BT40: 1729 | BU40: 908 | BV40: 6131 | BW40: 8936 | BX40: =IF(ISERROR(BW40/BK40-1),"",BW40/BK40-1) -> 1.0230926 | BY40: =IF(ISERROR(BW40/BV40-1),"",BW40/BV40-1) -> 0.45751101 | BZ40: =SUM(B40:M40) -> 0 | CA40: =SUM(N40:Y40) -> 0 | CB40: =SUM(Z40:AK40) -> 0 | CC40: =SUM(AL40:AW40) -> 20749 | CD40: =SUM(AX40:BI40) -> 80564 | CE40: =SUM(BJ40:BU40) -> 19879 | CF40: =SUM(BV40:BW40) -> 15067
A41: 雪佛兰Bolt EUV | AP41: 16 | AQ41: 625 | AR41: 1730 | AS41: 1494 | AT41: 11 | AU41: 7 | AW41: 3 | AX41: 13 | AY41: 48 | AZ41: 271 | BA41: 1159 | BB41: 1313 | BC41: 2724 | BD41: 4477 | BE41: 4783 | BF41: 4680 | BG41: 4996 | BH41: 3052 | BI41: 5033 | BJ41: 4297 | BK41: 5609 | BL41: 5469 | BM41: 4253 | BN41: 3195 | BO41: 4787 | BP41: 4002 | BQ41: 4438 | BR41: 4638 | BS41: 4315 | BT41: 3737 | BU41: 3390 | BV41: 0 | BW41: 3 | BX41: =IF(ISERROR(BW41/BK41-1),"",BW41/BK41-1) -> -0.99946515 | BY41: =IF(ISERROR(BW41/BV41-1),"",BW41/BV41-1) | BZ41: =SUM(B41:M41) -> 0 | CA41: =SUM(N41:Y41) -> 0 | CB41: =SUM(Z41:AK41) -> 0 | CC41: =SUM(AL41:AW41) -> 3886 | CD41: =SUM(AX41:BI41) -> 32549 | CE41: =SUM(BJ41:BU41) -> 52130 | CF41: =SUM(BV41:BW41) -> 3
A42: 斯柯达Enyaq iV | AK42: 741 | AL42: 91 | AM42: 6 | AN42: 120 | AO42: 2395 | AP42: 5380 | AQ42: 6108 | AR42: 3776 | AS42: 3636 | AT42: 5968 | AU42: 5262 | AV42: 5207 | AW42: 5923 | AX42: 3158 | AY42: 2693 | AZ42: 2970 | BA42: 3655 | BB42: 3776 | BC42: 5569 | BD42: 4547 | BE42: 4581 | BF42: 5081 | BG42: 4428 | BH42: 5124 | BI42: 6503 | BJ42: 3137 | BK42: 3484 | BL42: 4821 | BM42: 5014 | BN42: 6196 | BO42: 7152 | BP42: 7096 | BQ42: 8032 | BR42: 7396 | BS42: 8202 | BT42: 9079 | BU42: 8585 | BV42: 5207 | BW42: 5923 | BX42: =IF(ISERROR(BW42/BK42-1),"",BW42/BK42-1) -> 0.70005741 | BY42: =IF(ISERROR(BW42/BV42-1),"",BW42/BV42-1) -> 0.1375072 | BZ42: =SUM(B42:M42) -> 0 | CA42: =SUM(N42:Y42) -> 0 | CB42: =SUM(Z42:AK42) -> 741 | CC42: =SUM(AL42:AW42) -> 43872 | CD42: =SUM(AX42:BI42) -> 52085 | CE42: =SUM(BJ42:BU42) -> 78194 | CF42: =SUM(BV42:BW42) -> 11130
A43: ID.4 X | AN43: 625 | AO43: 922 | AP43: 847 | AQ43: 1100 | AR43: 2651 | AS43: 1686 | AT43: 3189 | AU43: 4195 | AV43: 3914 | AW43: 4045 | AX43: 4088 | AY43: 1357 | AZ43: 1527 | BA43: 539 | BB43: 2201 | BC43: 4571 | BD43: 5144 | BE43: 4561 | BF43: 1933 | BG43: 3034 | BH43: 4074 | BI43: 3608 | BJ43: 1135 | BK43: 680 | BL43: 1703 | BM43: 3601 | BN43: 2323 | BO43: 1733 | BP43: 841 | BQ43: 1913 | BR43: 3460 | BS43: 2653 | BT43: 2253 | BU43: 2344 | BV43: 3914 | BW43: 4045 | BX43: =IF(ISERROR(BW43/BK43-1),"",BW43/BK43-1) -> 4.9485294 | BY43: =IF(ISERROR(BW43/BV43-1),"",BW43/BV43-1) -> 0.033469596 | BZ43: =SUM(B43:M43) -> 0 | CA43: =SUM(N43:Y43) -> 0 | CB43: =SUM(Z43:AK43) -> 0 | CC43: =SUM(AL43:AW43) -> 23174 | CD43: =SUM(AX43:BI43) -> 36637 | CE43: =SUM(BJ43:BU43) -> 24639 | CF43: =SUM(BV43:BW43) -> 7959
A44: 蔚来ES6 | AI44: 883 | AJ44: 1518 | AK44: 2505 | AL44: 2845 | AM44: 2035 | AN44: 2576 | AO44: 2416 | AP44: 2282 | AQ44: 2830 | AR44: 2560 | AS44: 1800 | AT44: 3390 | AU44: 921 | AV44: 3482 | AW44: 4939 | AX44: 5247 | AY44: 3309 | AZ44: 5064 | BA44: 1878 | BB44: 2936 | BC44: 5100 | BD44: 4836 | BE44: 4507 | BF44: 3507 | BG44: 1970 | BH44: 1927 | BI44: 1731 | BJ44: 872 | BK44: 2848 | BL44: 853 | BM44: 174 | BN44: 1016 | BO44: 4677 | BP44: 11118 | BQ44: 8601 | BR44: 7918 | BS44: 5918 | BT44: 5697 | BU44: 6982 | BV44: 4713 | BW44: 4939 | BX44: =IF(ISERROR(BW44/BK44-1),"",BW44/BK44-1) -> 0.73419944 | BY44: =IF(ISERROR(BW44/BV44-1),"",BW44/BV44-1) -> 0.047952472 | BZ44: =SUM(B44:M44) -> 0 | CA44: =SUM(N44:Y44) -> 0 | CB44: =SUM(Z44:AK44) -> 4906 | CC44: =SUM(AL44:AW44) -> 32076 | CD44: =SUM(AX44:BI44) -> 42012 | CE44: =SUM(BJ44:BU44) -> 56674 | CF44: =SUM(BV44:BW44) -> 9652
...

Sheet 欧洲主要国家产销
Q12: 总销量同比 | AC12: 新能源汽车总销量
D14: 欧洲十国 | AD14: 法国 | AJ14: 挪威 | AP14: 瑞典 | AV14: 西班牙 | BB14: 英国 | BH14: 德国 | BN14: 瑞士 | BU14: 葡萄牙 | CB14: 意大利 | CI14: 丹麦
D15: 纯电动 | I15: 插电式 | N15: 新能源汽车合计 | S15: 汽车销量 | X15: 新能源汽车渗透率 | AD15: 纯电动 | AE15: 插电式 | AF15: 新能源汽车合计 | AG15: 汽车销量 | AH15: 新能源汽车渗透率 | AJ15: 纯电动 | AK15: 插电式 | AL15: 新能源汽车合计 | AM15: 汽车销量 | AN15: 新能源汽车渗透率 | AP15: 纯电动 | AQ15: 插电式 | AR15: 新能源汽车合计 | AS15: 汽车销量 | AT15: 新能源汽车渗透率 | AV15: 纯电动 | AW15: 插电式 | AX15: 新能源汽车合计 | AY15: 汽车销量 | AZ15: 新能源汽车渗透率 | BB15: 纯电动 | BC15: 插电式 | BD15: 新能源汽车合计 | BE15: 汽车销量 | BF15: 新能源汽车渗透率 | BH15: 纯电动 | BI15: 插电式 | BJ15: 新能源汽车合计 | BK15: 汽车销量 | BL15: 新能源汽车渗透率 | BN15: 纯电动 | BO15: 插电式 | BP15: 新能源汽车合计 | BQ15: 汽车销量 | BR15: 新能源汽车渗透率 | BU15: 纯电动 | BV15: 插电式 | BW15: 新能源汽车合计 | BX15: 汽车销量 | BY15: 新能源汽车渗透率 | CB15: 纯电动 | CC15: 插电式 | CD15: 新能源汽车合计 | CE15: 汽车销量 | CF15: 新能源汽车渗透率 | CI15: 纯电动 | CJ15: 插电式 | CK15: 新能源汽车合计 | CL15: 汽车销量 | CM15: 新能源汽车渗透率
C16: 万辆 | D16: 当月销量 | E16: 同比 | F16: 环比 | G16: 累计销量 | H16: 同比 | I16: 销量 | J16: 同比 | K16: 环比 | L16: 累计销量 | M16: 同比 | N16: 销量 | O16: 同比 | P16: 环比 | Q16: 累计销量 | R16: 同比 | S16: 销量 | T16: 同比 | U16: 环比 | V16: 累计销量 | W16: 同比 | X16: 渗透率 | Y16: 同比 | Z16: 环比 | AA16: 累计渗透率 | AB16: 同比
C17: 43466 | D17: =AD17+AJ17+AP17+AV17+BB17+BH17+BN17+BU17+CB17 -> 1.5681448 | G17: =SUM(D17) -> 1.5681448 | I17: =AE17+AK17+AQ17+AW17+BC17+BI17+BO17+BV17+CC17 -> 0.98132733 | L17: =I17 -> 0.98132733 | N17: =AF17+AL17+BD17+BJ17+AR17+AX17+BP17+BW17+CD17 -> 2.5494721 | Q17: =N17 -> 2.5494721 | S17: =AG17+AM17+AS17+AY17+BE17+BK17+BQ17+BX17+CE17 -> 88.764721 | V17: =S17 -> 88.764721 | X17: =N17/S17 -> 0.028721682 | AA17: =Q17/V17 -> 0.028721682 | AD17: 0.3059 | AE17: 0.1147 | AF17: =SUM(AD17:AE17) -> 0.4206 | AG17: 15.5079 | AH17: =AF17/AG17 -> 0.027121661 | AJ17: 0.3399679 | AK17: 0.12983762 | AL17: 0.46980552 | AM17: 0.90347215 | AN17: =AL17/AM17 -> 0.52 | AP17: 0.1084 | AQ17: 0.1566 | AR17: =SUM(AP17:AQ17) -> 0.265 | AS17: 2.0478 | AT17: =AR17/AS17 -> 0.12940717 | AV17: 0.080512594 | AW17: 0.051293706 | AX17: =AW17+AV17 -> 0.1318063 | AY17: 7.185 | AZ17: =AX17/AY17 -> 0.018344649 | BB17: 0.1334 | BC17: 0.2268 | BD17: 0.3602 | BE17: 16.1013 | BF17: =BD17/BE17 -> 0.022370864 | BH17: 0.46476427 | BI17: 0.211896 | BJ17: 0.67666027 | BK17: 26.569579 | BL17: =BJ17/BK17 -> 0.025467482 | BN17: 0.0434 | BO17: 0.0275 | BP17: =SUM(BN17:BO17) -> 0.0709 | BQ17: 2.0931 | BR17: =BP17/BQ17 -> 0.033873202 | BU17: 0.0683 | BV17: 0.0306 | BW17: =BV17+BU17 -> 0.0989 | BX17: 1.8294697 | BY17: =BW17/BX17 -> 0.054059383 | CB17: 0.0235 | CC17: 0.0321 | CD17: =CB17+CC17 -> 0.0556 | CE17: 16.5271 | CF17: =CD17/CE17 -> 0.0033641716
C18: 43498 | D18: =AD18+AJ18+AP18+AV18+BB18+BH18+BN18+BU18+CB18 -> 1.6163189 | F18: =D18/D17-1 -> 0.030720451 | G18: =G17+D18 -> 3.1844636 | I18: =AE18+AK18+AQ18+AW18+BC18+BI18+BO18+BV18+CC18 -> 0.93019642 | K18: =I18/I17-1 -> -0.052103825 | L18: =L17+I18 -> 1.9115237 | N18: =AF18+AL18+BD18+BJ18+AR18+AX18+BP18+BW18+CD18 -> 2.5465153 | P18: =N18/N17-1 -> -0.0011597671 | Q18: =Q17+N18 -> 5.0959874 | S18: =AG18+AM18+AS18+AY18+BE18+BK18+BQ18+BX18+CE18 -> 90.029305 | U18: =S18/S17-1 -> 0.014246474 | V18: =V17+S18 -> 178.79403 | X18: =N18/S18 -> 0.028285404 | Z18: =X18-X17 -> -0.00043627775 | AA18: =Q18/V18 -> 0.028502 | AD18: 0.2879 | AE18: 0.1277 | AF18: =SUM(AD18:AE18) -> 0.4156 | AG18: 17.2438 | AH18: =AF18/AG18 -> 0.024101416 | AJ18: 0.4516 | AK18: 0.1416 | AL18: 0.5932 | AM18: 1.1123153 | AN18: =AL18/AM18 -> 0.53330204 | AP18: 0.0896 | AQ18: 0.1892 | AR18: =SUM(AP18:AQ18) -> 0.2788 | AS18: 2.3146 | AT18: =AR18/AS18 -> 0.12045278 | AV18: 0.090696347 | AW18: 0.027906646 | AX18: =AW18+AV18 -> 0.11860299 | AY18: 11.9417 | AZ18: =AX18/AY18 -> 0.0099318349 | BB18: 0.0731 | BC18: 0.1373 | BD18: 0.2104 | BE18: 8.1969 | BF18: =BD18/BE18 -> 0.02566824 | BH18: 0.46382253 | BI18: 0.22018977 | BJ18: 0.6840123 | BK18: 26.899439 | BL18: =BJ18/BK18 -> 0.025428496 | BN18: 0.0733 | BO18: 0.0211 | BP18: =SUM(BN18:BO18) -> 0.0944 | BQ18: 2.2176 | BR18: =BP18/BQ18 -> 0.042568543 | BU18: 0.0563 | BV18: 0.0297 | BW18: =BV18+BU18 -> 0.086 | BX18: 2.2536507 | BY18: =BW18/BX18 -> 0.038160306 | CB18: 0.03 | CC18: 0.0355 | CD18: =CB18+CC18 -> 0.0655 | CE18: 17.8493 | CF18: =CD18/CE18 -> 0.0036696117
C19: 43527 | D19: =AD19+AJ19+AP19+AV19+BB19+BH19+BN19+BU19+CB19 -> 3.2952725 | F19: =D19/D18-1 -> 1.0387515 | G19: =G18+D19 -> 6.4797362 | I19: =AE19+AK19+AQ19+AW19+BC19+BI19+BO19+BV19+CC19 -> 1.5704351 | K19: =I19/I18-1 -> 0.68828332 | L19: =L18+I19 -> 3.4819588 | N19: =AF19+AL19+BD19+BJ19+AR19+AX19+BP19+BW19+CD19 -> 4.8657076 | P19: =N19/N18-1 -> 0.91073175 | Q19: =Q18+N19 -> 9.961695 | S19: =AG19+AM19+AS19+AY19+BE19+BK19+BQ19+BX19+CE19 -> 144.36911 | U19: =S19/S18-1 -> 0.60357905 | V19: =V18+S19 -> 323.16313 | X19: =N19/S19 -> 0.033703246 | Z19: =X19-X18 -> 0.0054178421 | AA19: =Q19/V19 -> 0.030825592 | AD19: 0.4614 | AE19: 0.151 | AF19: =SUM(AD19:AE19) -> 0.6124 | AG19: 22.5818 | AH19: =AF19/AG19 -> 0.027119184 | AJ19: 1.0732 | AK19: 0.2036 | AL19: 1.2768 | AM19: 1.8376712 | AN19: =AL19/AM19 -> 0.6947924 | AP19: 0.2111 | AQ19: 0.2288 | AR19: =SUM(AP19:AQ19) -> 0.4399 | AS19: 3.0256 | AT19: =AR19/AS19 -> 0.14539265 | AV19: 0.14838129 | AW19: 0.078696742 | AX19: =AW19+AV19 -> 0.22707804 | AY19: 12.5623 | AZ19: =AX19/AY19 -> 0.018076151 | BB19: 0.3932 | BC19: 0.4941 | BD19: 0.8873 | BE19: 45.8054 | BF19: =BD19/BE19 -> 0.019371079 | BH19: 0.66169122 | BI19: 0.30613836 | BJ19: 0.96782958 | BK19: 34.529535 | BL19: =BJ19/BK19 -> 0.028029036 | BN19: 0.1856 | BO19: 0.0316 | BP19: =SUM(BN19:BO19) -> 0.2172 | BQ19: 2.8958 | BR19: =BP19/BQ19 -> 0.07500518 | BU19: 0.0985 | BV19: 0.0307 | BW19: =BV19+BU19 -> 0.1292 | BX19: 1.7008026 | BY19: =BW19/BX19 -> 0.075964137 | CB19: 0.0622 | CC19: 0.0458 | CD19: =CB19+CC19 -> 0.108 | CE19: 19.4302 | CF19: =CD19/CE19 -> 0.0055583576
